Workbook

Sheet Intro
B2: Hardness-EC Trade-Offs | C2: 1) Ni–Si base | D2: Solution ==> Quenching ==> Deformation ==> Aging ==> Secondary TMP ==> Secondary Aging (2); Solution ==> Quenching ==> Aging (0); Solution ==> Quenching ==> Deformation ==> Aging (1)
C3: Cu-Ni-Si
C4: 2) Ni–Si + modifiers（Ni–Si 体系调控版）
C5: Cu-Mg-Ni-Si
C6: Cu-Ni-Si-Zr
C7: 3) Cr base / Cr + modifiers
C8: Cu-Cr-Zr
C9: Cu-Cr-Mg
C10: 4) Cr–Ni–Si hybrid（含 Cr 且含 Ni+Si）
C11: Cu-Cr-Ni-Si
C12: Cu-Cr-Ni-Si-Zr
C13: Cu-Cr-Mg-Ni-Si
C14: Cu-Al-Cr-Mg-Ni-Si
B16: UTS Prediction | C16: 1) Ni–Si base（Ni–Si 主体系）
C17: Cu–Ni–Si
C19: 2) Ni–Si + modifiers
C20: Cu–Ni–Si–Zr、Cu–Mg–Ni–Si、Cu–Ni–Si–Ti
C22: 3) Cr base / Cr + modifiers（Cr 主体系
C23: Cu–Cr、Cu–Cr–Zr、Cu–Cr–Mg、Cu–Cr–Fe
C25: 4) Hybrid / Other（复合或其它主体系）
C26: Cr–Ni–Si 复合、Cr–Ti 复合、Ni–Si–Ti 复合，以及 Cu–Ti 系、Cu–Fe 系

Sheet All
A1: ID | B1: DOI | C1: Alloy-Series | D1: Cu/wt.% | E1: Al/wt.% | F1: Cr/wt.% | G1: Fe/wt.% | H1: Mg/wt.% | I1: Ni/wt.% | J1: P/wt.% | K1: Si/wt.% | L1: Ti/wt.% | M1: Zr/wt.% | N1: Processing_route | O1: Solution_Temperature/℃ | P1: Solution_Time/h | Q1: CR_Reduction/% | R1: Aging_Temperature/℃ | S1: Aging_Time/h | T1: Secondary TMP | U1: Hardness/HV | V1: YS | W1: UTS | X1: EC/%IACS
A2: 1 | B2: 10.1023/A:1004830000742 | C2: Cu-Mg-Ni-P-Si | D2: 98.12 | E2: 0 | F2: 0 | G2: 0 | H2: 0.05 | I2: 1.5 | J2: 0.03 | K2: 0.3 | L2: 0 | M2: 0 | N2: Solution ==> Quenching ==> Deformation ==> Aging | O2: 699.85 | P2: 4 | Q2: 85 | R2: 449.85 | S2: 2 | T2: N | U2: 174 | V2: N/A | W2: N/A | X2: 86
A3: 5 | B3: 10.3390/ma12132076 | C3: Cu-Ni-Si | D3: 95.935 | E3: 0 | F3: 0 | G3: 0 | H3: 0 | I3: 3.3 | J3: 0 | K3: 0.765 | L3: 0 | M3: 0 | N3: Solution ==> Quenching ==> Aging | O3: 899.85 | P3: 1 | Q3: 0 | R3: 449.85 | S3: 0.25 | T3: N | U3: 137 | V3: N/A | W3: N/A | X3: 27
A4: 6 | B4: 10.3390/ma12132076 | C4: Cu-Ni-Si | D4: 95.935 | E4: 0 | F4: 0 | G4: 0 | H4: 0 | I4: 3.3 | J4: 0 | K4: 0.765 | L4: 0 | M4: 0 | N4: Solution ==> Quenching ==> Aging | O4: 899.85 | P4: 1 | Q4: 0 | R4: 499.85 | S4: 0.25 | T4: N | U4: 161 | V4: N/A | W4: N/A | X4: 28
A5: 7 | B5: 10.3390/ma12132076 | C5: Cu-Ni-Si | D5: 95.935 | E5: 0 | F5: 0 | G5: 0 | H5: 0 | I5: 3.3 | J5: 0 | K5: 0.765 | L5: 0 | M5: 0 | N5: Solution ==> Quenching ==> Deformation ==> Aging | O5: 899.85 | P5: 1 | Q5: 60 | R5: 449.85 | S5: 0.25 | T5: N | U5: 246 | V5: N/A | W5: N/A | X5: 29
A6: 8 | B6: 10.3390/ma12132076 | C6: Cu-Ni-Si | D6: 95.935 | E6: 0 | F6: 0 | G6: 0 | H6: 0 | I6: 3.3 | J6: 0 | K6: 0.765 | L6: 0 | M6: 0 | N6: Solution ==> Quenching ==> Deformation ==> Aging | O6: 899.85 | P6: 1 | Q6: 60 | R6: 499.85 | S6: 0.25 | T6: N | U6: 254 | V6: N/A | W6: N/A | X6: 32
A7: 9 | B7: 10.3390/ma12132076 | C7: Cu-Ni-Si | D7: 95.935 | E7: 0 | F7: 0 | G7: 0 | H7: 0 | I7: 3.3 | J7: 0 | K7: 0.765 | L7: 0 | M7: 0 | N7: Solution ==> Quenching ==> Deformation ==> Aging ==> Secondary TMP ==> Secondary Aging | O7: 899.85 | P7: 1 | Q7: 45 | R7: 349.85 | S7: 0.25 | T7: Y | U7: 280 | V7: N/A | W7: N/A | X7: 37
A8: 10 | B8: 10.3390/ma14081996 | C8: Cu-Ni-Si | D8: 95.7 | E8: 0 | F8: 0 | G8: 0 | H8: 0 | I8: 3.48 | J8: 0 | K8: 0.82 | L8: 0 | M8: 0 | N8: Solution ==> Quenching ==> Aging | O8: 899.85 | P8: 1 | Q8: 0 | R8: 499.85 | S8: 0.25 | T8: N | U8: 201 | V8: N/A | W8: N/A | X8: 31
A9: 12 | B9: 10.3390/ma12132076 | C9: Cu-Ni-Si | D9: 95.935 | E9: 0 | F9: 0 | G9: 0 | H9: 0 | I9: 3.3 | J9: 0 | K9: 0.765 | L9: 0 | M9: 0 | N9: Solution ==> Quenching ==> Aging | O9: 899.85 | P9: 1 | Q9: 0 | R9: 449.85 | S9: 0.5 | T9: N | U9: 151 | V9: N/A | W9: N/A | X9: 28
A10: 13 | B10: 10.3390/ma12132076 | C10: Cu-Ni-Si | D10: 95.935 | E10: 0 | F10: 0 | G10: 0 | H10: 0 | I10: 3.3 | J10: 0 | K10: 0.765 | L10: 0 | M10: 0 | N10: Solution ==> Quenching ==> Aging | O10: 899.85 | P10: 1 | Q10: 0 | R10: 499.85 | S10: 0.5 | T10: N | U10: 205 | V10: N/A | W10: N/A | X10: 32
A11: 14 | B11: 10.3390/ma12132076 | C11: Cu-Ni-Si | D11: 95.935 | E11: 0 | F11: 0 | G11: 0 | H11: 0 | I11: 3.3 | J11: 0 | K11: 0.765 | L11: 0 | M11: 0 | N11: Solution ==> Quenching ==> Deformation ==> Aging | O11: 899.85 | P11: 1 | Q11: 60 | R11: 449.85 | S11: 0.5 | T11: N | U11: 255 | V11: N/A | W11: N/A | X11: 38
A12: 15 | B12: 10.3390/ma12132076 | C12: Cu-Ni-Si | D12: 95.935 | E12: 0 | F12: 0 | G12: 0 | H12: 0 | I12: 3.3 | J12: 0 | K12: 0.765 | L12: 0 | M12: 0 | N12: Solution ==> Quenching ==> Deformation ==> Aging | O12: 899.85 | P12: 1 | Q12: 60 | R12: 499.85 | S12: 0.5 | T12: N | U12: 246 | V12: N/A | W12: N/A | X12: 34
A13: 16 | B13: 10.3390/ma12132076 | C13: Cu-Ni-Si | D13: 95.935 | E13: 0 | F13: 0 | G13: 0 | H13: 0 | I13: 3.3 | J13: 0 | K13: 0.765 | L13: 0 | M13: 0 | N13: Solution ==> Quenching ==> Deformation ==> Aging ==> Secondary TMP ==> Secondary Aging | O13: 899.85 | P13: 1 | Q13: 45 | R13: 349.85 | S13: 0.5 | T13: Y | U13: 282 | V13: N/A | W13: N/A | X13: 37
... A217: 261 | B217: 10.1016/j.msea.2006.07.121 | C217: Cu-Cr-Mg | D217: 99.53 | E217: 0 | F217: 0.28 | G217: 0 | H217: 0.19 | I217: 0 | J217: 0 | K217: 0 | L217: 0 | M217: 0 | N217: Solution ==> Quenching ==> Aging | O217: 949.85 | P217: 4 | Q217: 0 | R217: 509.85 | S217: 0.25 | T217: N | U217: 77 | V217: N/A | W217: N/A | X217: 54
A218: 262 | B218: 10.1007/s11665-016-1987-6 and 10.1515/ntre-2019-0034 | C218: Cu-Ni-P-Si | D218: 97.585 | E218: 0 | F218: 0 | G218: 0 | H218: 0 | I218: 1.91 | J218: 0.035 | K218: 0.47 | L218: 0 | M218: 0 | N218: Solution ==> Quenching ==> Aging | O218: 949.85 | P218: 1 | Q218: 0 | R218: 399.85 | S218: 0.25 | T218: N | U218: N/A | V218: 173/MPa | W218: N/A | X218: 28
A219: 263 | B219: 10.1007/s11665-016-1987-6 and 10.1515/ntre-2019-0034 | C219: Cu-Ni-P-Si | D219: 97.585 | E219: 0 | F219: 0 | G219: 0 | H219: 0 | I219: 1.91 | J219: 0.035 | K219: 0.47 | L219: 0 | M219: 0 | N219: Solution ==> Quenching ==> Aging | O219: 949.85 | P219: 1 | Q219: 0 | R219: 449.85 | S219: 0.25 | T219: N | U219: N/A | V219: 185/MPa | W219: N/A | X219: 31
A220: 264 | B220: 10.1007/s11665-016-1987-6 and 10.1515/ntre-2019-0034 | C220: Cu-Ni-P-Si | D220: 97.585 | E220: 0 | F220: 0 | G220: 0 | H220: 0 | I220: 1.91 | J220: 0.035 | K220: 0.47 | L220: 0 | M220: 0 | N220: Solution ==> Quenching ==> Aging | O220: 949.85 | P220: 1 | Q220: 0 | R220: 499.85 | S220: 0.25 | T220: N | U220: N/A | V220: 210/MPa | W220: N/A | X220: 27
A221: 266 | B221: 10.1007/s11665-016-1987-6 and 10.1515/ntre-2019-0034 | C221: Cu-Ni-P-Si | D221: 97.585 | E221: 0 | F221: 0 | G221: 0 | H221: 0 | I221: 1.91 | J221: 0.035 | K221: 0.47 | L221: 0 | M221: 0 | N221: Solution ==> Quenching ==> Deformation ==> Aging | O221: 949.85 | P221: 1 | Q221: 60 | R221: 449.85 | S221: 0.25 | T221: N | U221: N/A | V221: 219/MPa | W221: N/A | X221: 32
A222: 267 | B222: 10.1007/s11665-016-1987-6 and 10.1515/ntre-2019-0034 | C222: Cu-Ni-P-Si | D222: 97.585 | E222: 0 | F222: 0 | G222: 0 | H222: 0 | I222: 1.91 | J222: 0.035 | K222: 0.47 | L222: 0 | M222: 0 | N222: Solution ==> Quenching ==> Deformation ==> Aging | O222: 949.85 | P222: 1 | Q222: 80 | R222: 449.85 | S222: 0.25 | T222: N | U222: N/A | V222: 223/MPa | W222: N/A | X222: 23
A223: 269 | B223: 10.2320/jinstmet1952.62.4_301 | C223: Cu-Ni-Si | D223: 97.943 | E223: 0 | F223: 0 | G223: 0 | H223: 0 | I223: 1.39 | J223: 0 | K223: 0.67 | L223: 0 | M223: 0 | N223: Solution ==> Quenching ==> Aging | O223: 949.85 | P223: 1 | Q223: 0 | R223: 499.85 | S223: 0.33333333 | T223: N | U223: 72 | V223: N/A | W223: N/A | X223: 21
A224: 270 | B224: 10.2320/jinstmet1952.62.4_301 | C224: Cu-Ni-Si | D224: 94.402 | E224: 0 | F224: 0 | G224: 0 | H224: 0 | I224: 3.77 | J224: 0 | K224: 1.83 | L224: 0 | M224: 0 | N224: Solution ==> Quenching ==> Aging | O224: 949.85 | P224: 1 | Q224: 0 | R224: 499.85 | S224: 0.33333333 | T224: N | U224: 218 | V224: N/A | W224: N/A | X224: 16
A225: 271 | B225: 10.2320/jinstmet1952.62.4_301 | C225: Cu-Ni-Si | D225: 98.283 | E225: 0 | F225: 0 | G225: 0 | H225: 0 | I225: 1.38 | J225: 0 | K225: 0.33 | L225: 0 | M225: 0 | N225: Solution ==> Quenching ==> Aging | O225: 949.85 | P225: 1 | Q225: 0 | R225: 499.85 | S225: 0.33333333 | T225: N | U225: 67 | V225: N/A | W225: N/A | X225: 30
A226: 272 | B226: 10.2320/jinstmet1952.62.4_301 | C226: Cu-Ni-Si | D226: 97.128 | E226: 0 | F226: 0 | G226: 0 | H226: 0 | I226: 2.32 | J226: 0 | K226: 0.56 | L226: 0 | M226: 0 | N226: Solution ==> Quenching ==> Aging | O226: 949.85 | P226: 1 | Q226: 0 | R226: 499.85 | S226: 0.33333333 | T226: N | U226: 186 | V226: N/A | W226: N/A | X226: 44
A227: 273 | B227: 10.2320/jinstmet1952.62.4_301 | C227: Cu-Ni-Si | D227: 95.339 | E227: 0 | F227: 0 | G227: 0 | H227: 0 | I227: 3.77 | J227: 0 | K227: 0.89 | L227: 0 | M227: 0 | N227: Solution ==> Quenching ==> Aging | O227: 949.85 | P227: 1 | Q227: 0 | R227: 499.85 | S227: 0.33333333 | T227: N | U227: 222 | V227: N/A | W227: N/A | X227: 35
A228: 274 | B228: 10.2320/jinstmet1952.62.4_301 | C228: Cu-Ni-Si | D228: 98.347 | E228: 0 | F228: 0 | G228: 0 | H228: 0 | I228: 1.38 | J228: 0 | K228: 0.27 | L228: 0 | M228: 0 | N228: Solution ==> Quenching ==> Aging | O228: 949.85 | P228: 1 | Q228: 0 | R228: 499.85 | S228: 0.33333333 | T228: N | U228: 70 | V228: N/A | W228: N/A | X228: 32
A229: 275 | B229: 10.2320/jinstmet1952.62.4_301 | C229: Cu-Ni-Si | D229: 97.24 | E229: 0 | F229: 0 | G229: 0 | H229: 0 | I229: 2.31 | J229: 0 | K229: 0.45 | L229: 0 | M229: 0 | N229: Solution ==> Quenching ==> Aging | O229: 949.85 | P229: 1 | Q229: 0 | R229: 499.85 | S229: 0.33333333 | T229: N | U229: 165 | V229: N/A | W229: N/A | X229: 40
A230: 276 | B230: 10.2320/jinstmet1952.62.4_301 | C230: Cu-Ni-Si | D230: 95.518 | E230: 0 | F230: 0 | G230: 0 | H230: 0 | I230: 3.78 | J230: 0 | K230: 0.71 | L230: 0 | M230: 0 | N230: Solution ==> Quenching ==> Aging | O230: 949.85 | P230: 1 | Q230: 0 | R230: 499.85 | S230: 0.33333333 | T230: N | U230: 200 | V230: N/A | W230: N/A | X230: 35
A231: 277 | B231: 10.2320/jinstmet1952.62.4_301 | C231: Cu-Ni-Si | D231: 98.393 | E231: 0 | F231: 0 | G231: 0 | H231: 0 | I231: 1.39 | J231: 0 | K231: 0.22 | L231: 0 | M231: 0 | N231: Solution ==> Quenching ==> Aging | O231: 949.85 | P231: 1 | Q231: 0 | R231: 499.85 | S231: 0.33333333 | T231: N | U231: 60 | V231: N/A | W231: N/A | X231: 36
A232: 278 | B232: 10.2320/jinstmet1952.62.4_301 | C232: Cu-Ni-Si | D232: 93.886 | E232: 0 | F232: 0 | G232: 0 | H232: 0 | I232: 2.3 | J232: 0 | K232: 3.81 | L232: 0 | M232: 0 | N232: Solution ==> Quenching ==> Aging | O232: 949.85 | P232: 1 | Q232: 0 | R232: 499.85 | S232: 0.33333333 | T232: N | U232: 158 | V232: N/A | W232: N/A | X232: 39
A233: 279 | B233: 10.2320/jinstmet1952.62.4_301 | C233: Cu-Ni-Si | D233: 95.627 | E233: 0 | F233: 0 | G233: 0 | H233: 0 | I233: 3.76 | J233: 0 | K233: 0.61 | L233: 0 | M233: 0 | N233: Solution ==> Quenching ==> Aging | O233: 949.85 | P233: 1 | Q233: 0 | R233: 499.85 | S233: 0.33333333 | T233: N | U233: 189 | V233: N/A | W233: N/A | X233: 32
A234: 280 | B234: 10.1016/j.msea.2006.07.121 | C234: Cu-Cr-Mg | D234: 99.53 | E234: 0 | F234: 0.28 | G234: 0 | H234: 0.19 | I234: 0 | J234: 0 | K234: 0 | L234: 0 | M234: 0 | N234: Solution ==> Quenching ==> Aging | O234: 949.85 | P234: 4 | Q234: 0 | R234: 389.85 | S234: 0.5 | T234: N | U234: 67 | V234: N/A | W234: N/A | X234: 50
... A238: 284 | B238: 10.1016/j.msea.2006.07.121 | C238: Cu-Cr-Mg | D238: 99.53 | E238: 0 | F238: 0.28 | G238: 0 | H238: 0.19 | I238: 0 | J238: 0 | K238: 0 | L238: 0 | M238: 0 | N238: Solution ==> Quenching ==> Aging | O238: 949.85 | P238: 4 | Q238: 0 | R238: 509.85 | S238: 0.5 | T238: N | U238: 82 | V238: N/A | W238: N/A | X238: 62
A239: 287 | B239: 10.1007/s11665-016-1987-6 and 10.1515/ntre-2019-0034 | C239: Cu-Ni-P-Si | D239: 97.585 | E239: 0 | F239: 0 | G239: 0 | H239: 0 | I239: 1.91 | J239: 0.035 | K239: 0.47 | L239: 0 | M239: 0 | N239: Solution ==> Quenching ==> Aging | O239: 949.85 | P239: 1 | Q239: 0 | R239: 399.85 | S239: 0.5 | T239: N | U239: N/A | V239: 180/MPa | W239: N/A | X239: 30
A240: 288 | B240: 10.1007/s11665-016-1987-6 and 10.1515/ntre-2019-0034 | C240: Cu-Ni-P-Si | D240: 97.585 | E240: 0 | F240: 0 | G240: 0 | H240: 0 | I240: 1.91 | J240: 0.035 | K240: 0.47 | L240: 0 | M240: 0 | N240: Solution ==> Quenching ==> Aging | O240: 949.85 | P240: 1 | Q240: 0 | R240: 449.85 | S240: 0.5 | T240: N | U240: N/A | V240: 200/MPa | W240: N/A | X240: 30
A241: 289 | B241: 10.1007/s11665-016-1987-6 and 10.1515/ntre-2019-0034 | C241: Cu-Ni-P-Si | D241: 97.585 | E241: 0 | F241: 0 | G241: 0 | H241: 0 | I241: 1.91 | J241: 0.035 | K241: 0.47 | L241: 0 | M241: 0 | N241: Solution ==> Quenching ==> Aging | O241: 949.85 | P241: 1 | Q241: 0 | R241: 499.85 | S241: 0.5 | T241: N | U241: N/A | V241: 219/MPa | W241: N/A | X241: 28
A242: 291 | B242: 10.1007/s11665-016-1987-6 and 10.1515/ntre-2019-0034 | C242: Cu-Ni-P-Si | D242: 97.585 | E242: 0 | F242: 0 | G242: 0 | H242: 0 | I242: 1.91 | J242: 0.035 | K242: 0.47 | L242: 0 | M242: 0 | N242: Solution ==> Quenching ==> Deformation ==> Aging | O242: 949.85 | P242: 1 | Q242: 60 | R242: 449.85 | S242: 0.5 | T242: N | U242: N/A | V242: 222/MPa | W242: N/A | X242: 33
A243: 292 | B243: 10.1007/s11665-016-1987-6 and 10.1515/ntre-2019-0034 | C243: Cu-Ni-P-Si | D243: 97.585 | E243: 0 | F243: 0 | G243: 0 | H243: 0 | I243: 1.91 | J243: 0.035 | K243: 0.47 | L243: 0 | M243: 0 | N243: Solution ==> Quenching ==> Deformation ==> Aging | O243: 949.85 | P243: 1 | Q243: 80 | R243: 449.85 | S243: 0.5 | T243: N | U243: N/A | V243: 226/MPa | W243: N/A | X243: 35
A244: 293 | B244: 10.1016/j.matdes.2021.109929 | C244: Cu-Ni-Si | D244: 96.3 | E244: 0 | F244: 0 | G244: 0 | H244: 0 | I244: 3 | J244: 0 | K244: 0.7 | L244: 0 | M244: 0 | N244: Solution ==> Quenching ==> Aging | O244: 949.85 | P244: 3 | Q244: 0 | R244: 449.85 | S244: 0.5 | T244: N | U244: 230 | V244: N/A | W244: N/A | X244: 34
A245: 294 | B245: 10.1016/j.msea.2006.07.121 | C245: Cu-Cr-Mg | D245: 99.53 | E245: 0 | F245: 0.28 | G245: 0 | H245: 0.19 | I245: 0 | J245: 0 | K245: 0 | L245: 0 | M245: 0 | N245: Solution ==> Quenching ==> Aging | O245: 949.85 | P245: 4 | Q245: 0 | R245: 389.85 | S245: 1 | T245: N | U245: 77 | V245: N/A | W245: N/A | X245: 55
A246: 295 | B246: 10.1016/j.msea.2006.07.121 | C246: Cu-Cr-Mg | D246: 99.53 | E246: 0 | F246: 0.28 | G246: 0 | H246: 0.19 | I246: 0 | J246: 0 | K246: 0 | L246: 0 | M246: 0 | N246: Solution ==> Quenching ==> Aging | O246: 949.85 | P246: 4 | Q246: 0 | R246: 419.85 | S246: 1 | T246: N | U246: 108 | V246: N/A | W246: N/A | X246: 66
...

Sheet Hardness-EC
D1: Ni–Si base + Ni–Si + modifiers: NiSi_family (0) | M1: Elemental Melting point | N1: 1084.62 | O1: 660.32 | P1: 1907 | Q1: 650 | R1: 1455 | S1: 1414 | T1: 1855
D2: Cr base / Cr + modifiers: Cr_family (1) | M2: Valence Electron Count | N2: 11 | O2: 3 | P2: 6 | Q2: 2 | R2: 10 | S2: 4 | T2: 4 | U2: N | AS2: Solution ==> Quenching ==> Deformation ==> Aging ==> Secondary TMP ==> Secondary Aging (2) | AZ2: 冷变形后在时效中的累计作用量，反映位错辅助析出的“持续剂量” | BB2: 固溶时效温差代理过饱和度与析出潜力
D3: Cr–Ni–Si hybrid (含 Cr 且含 Ni+Si): Hybrid_family (2) | M3: Pauling Electronegativity | N3: 1.9 | O3: 1.61 | P3: 1.66 | Q3: 1.31 | R3: 1.91 | S3: 1.9 | T3: 1.33 | U3: N | AI3: Atomic-Size-Mismatch | AK3: Pauling-Electronegativity | AL3: Valence-Electron-Concentration | AM3: VEC | AP3: Herfindahl–Hirschman Index | AQ3: 1/HHI | AS3: Solution ==> Quenching ==> Aging (0) | AY3: 冷加工缺陷 × 扩散温度窗口，形变诱导析出/回复驱动力强弱 | BA3: 时效强弱总量指标控制析出进程、EC恢复程度与过时效风险 | BI3: SQRT{(z(HV)-z(HV)^*)^2+(z(100-EC)-z(100-EC)^*)^2}
D4: Alloy_Family | E4: 元素质量分数 | F4: 63.546 | G4: 26.982 | H4: 51.996 | I4: 24.305 | J4: 58.693 | K4: 28.085 | L4: 91.224 | M4: 金属原子半径/Å | N4: 1.28 | O4: 1.43 | P4: 1.28 | Q4: 1.6 | R4: 1.24 | S4: 1.11 | T4: 1.6 | U4: Sum-Atom | V4: W{Ni}/W{Si} | W4: W{Ni}+W{Si} | X4: W{Ni}*W{Si} | Y4: W{Mg}/W{Ni+Si} | Z4: W{Zr}/W{Ni+Si} | AA4: W{Cr}/W{Zr} | AB4: W{Cr}+W{Zr} | AC4: W{Cr}*W{Zr} | AD4: W{Mg}/W{Cr} | AE4: W{Cr}/W{Ni+Si} | AF4: W{Ni+Si}/W{Cr} | AG4: Hybrid_index | AH4: Total_Alloying | AI4: 尺寸错配 | AJ4: 平均化学键合特征 | AK4: 电负性方差 | AL4: 价电子浓度方差 | AM4: 价电子浓度 | AN4: 熔点 | AO4: 混合熵 | AP4: 成分集中度 | AQ4: 等效参与元素数 | AS4: Solution ==> Quenching ==> Deformation ==> Aging (1) | AY4: 形变×扩散耦 | AZ4: 形变×时效量 | BA4: 时效强度 | BB4: 过饱和窗口 | BH4: z(Hardness) - lambda*z(100-EC)
A5: ID | B5: DOI | C5: Alloy-Series | D5: Family | E5: 元素名称 | F5: Cu/wt.% | G5: Al/wt.% | H5: Cr/wt.% | I5: Mg/wt.% | J5: Ni/wt.% | K5: Si/wt.% | L5: Zr/wt.% | M5: 元素名称 | N5: Cu/at.% | O5: Al/at.% | P5: Cr/at.% | Q5: Mg/at.% | R5: Ni/at.% | S5: Si/at.% | T5: Zr/at.% | U5: Sum-Atom | V5: Ni/Si | W5: Ni+Si | X5: Ni*Si | Y5: Mg/(Ni+Si) | Z5: Zr/(Ni+Si) | AA5: Cr/Zr | AB5: Cr+Zr | AC5: Cr*Zr | AD5: Mg/Cr | AE5: Cr/(Ni+Si) | AF5: W{Ni+Si}/W{Cr} | AG5: W{Ni+Si}*W{Cr} | AH5: TAlloying | AI5: δ | AJ5: χavg | AK5: χvar | AL5: VECvar | AM5: VECavg | AN5: Tmavg | AO5: Smix | AP5: HHI | AQ5: N_eff | AR5: Processing_route | AS5: One-Hot-Processing | AT5: Solution_Temperature/℃ | AU5: Solution_Time/h | AV5: CR_Reduction/% | AW5: Aging_Temperature/℃ | AX5: Aging_Time/h | AY5: CR_x_ATem | AZ5: CR_x_Atime | BA5: ATem_x_Atime | BB5: STem-ATem | BC5: Secondary TMP | BD5: Hardness/HV | BE5: YS | BF5: UTS | BG5: EC/%IACS | BH5: Q3 | BI5: Q3-Euclidean
A6: 1173 | B6: 10.1016/j.jallcom.2016.11.137 | C6: =_xlfn.XLOOKUP(A6,All!$A:$A,All!$C:$C,"") -> Cu-Al-Cr-Mg-Ni-Si | D6: 2 | E6: 质量分数 | F6: =100-SUM(G6:L6) -> 92.25 | G6: 0.5 | H6: 0.1 | I6: 0.15 | J6: 6 | K6: 1 | L6: 0 | M6: 摩尔分数 | N6: {=(F6/$F$4)/SUMPRODUCT($F6:$L6/$F$4:$L$4)*100} -> 89.824126 | O6: {=(G6/$G$4)/SUMPRODUCT($F6:$L6/$F$4:$L$4)*100} -> 1.1465968 | P6: {=(H6/$H$4)/SUMPRODUCT($F6:$L6/$F$4:$L$4)*100} -> 0.11899944 | Q6: {=(I6/$I$4)/SUMPRODUCT($F6:$L6/$F$4:$L$4)*100} -> 0.38186555 | R6: {=(J6/$J$4)/SUMPRODUCT($F6:$L6/$F$4:$L$4)*100} -> 6.3252805 | S6: {=(K6/$K$4)/SUMPRODUCT($F6:$L6/$F$4:$L$4)*100} -> 2.2031315 | T6: {=(L6/$L$4)/SUMPRODUCT($F6:$L6/$F$4:$L$4)*100} -> 0 | U6: =SUM(N6:T6) -> 100 | V6: =IF(K6<>0,J6/(K6),0) -> 6 | W6: =J6+K6 -> 7 | X6: =J6*K6 -> 6 | Y6: =IF(J6+K6<>0,I6/(J6+K6),0) -> 0.021428571 | Z6: =IF(J6+K6<>0,L6/(J6+K6),0) -> 0 | AA6: =IF(L6<>0,H6/(L6),0) -> 0 | AB6: =H6+L6 -> 0.1 | AC6: =H6*L6 -> 0 | AD6: =IF(H6<>0,P6/(H6),0) -> 1.1899944 | AE6: =IF(J6+K6<>0,H6/(J6+K6),0) -> 0.014285714 | AF6: =IF(H6<>0,(J6+K6)/(H6),0) -> 70 | AG6: =(J6+K6)*H6 -> 0.7 | AH6: =(100-N6)% -> 0.10175874 | AI6: {=SQRT(SUMPRODUCT(N6:T6/100,(1-($N$4:$T$4/(SUMPRODUCT(N6:T6,$N$4:$T$4)/100)))^2))} -> 0.029053738 | AJ6: {=SUMPRODUCT(N6:T6,$N$3:$T$3)/100} -> 1.8947688 | AK6: {=SUMPRODUCT(N6:T6/100,($N$3:$T$3-(SUMPRODUCT(N6:T6,$N$3:$T$3)/100))^2)} -> 0.0023410653 | AL6: {=SUMPRODUCT(N6:T6/100,($N$2:$T$2-(SUMPRODUCT(N6:T6,$N$2:$T$2)/100))^2)} -> 2.0935075 | AM6: {=SUMPRODUCT(N6:T6,$N$2:$T$2)/100} -> 10.650482 | AN6: {=SUMPRODUCT(N6:T6,$N$1:$T$1)/100} -> 1109.7582 | AO6: {=-8.314*SUMPRODUCT((N6:T6/100)*LN(N6:T6/100+0.000000000001))} -> 3.6213944 | AP6: {=SUMPRODUCT((N6:T6/100)^2)} -> 0.81147113 | AQ6: {=1/SUMPRODUCT((N6:T6/100)^2)} -> 1.2323297 | AR6: Solution ==> Quenching ==> Deformation ==> Aging ==> Secondary TMP ==> Secondary Aging | AS6: =IF(AR6="Solution ==> Quenching ==> Deformation ==> Aging ==> Secondary TMP ==> Secondary Aging",2,IF(AR6="Solution ==> Quenching ==> Deformation ==> Aging",1,IF(AR6="Solution ==> Quenching ==> Aging",0,""))) -> 2 | AT6: 979.85 | AU6: 4 | AV6: 50 | AW6: 399.85 | AX6: 8 | AY6: =AV6%*AW6 -> 199.925 | AZ6: =AV6%*AX6 -> 4 | BA6: =AW6*AX6 -> 3198.8 | BB6: =AT6-AW6 -> 580 | BC6: Y | BD6: 166 | BE6: N/A | BF6: N/A | BG6: 64 | BH6: =IF(OR(BD6="",BG6=""),"",((BD6-AVERAGE($BD$6:$BD$1143))/_xlfn.STDEV.S($BD$6:$BD$1143))-$BJ$1*((AVERAGE($BG$6:$BG$1143)-BG6)/_xlfn.STDEV.S($BG$6:$BG$1143))) -> -0.58945564 | BI6: =SQRT((1-(BD6-MIN($BD$6:$BD$1143))/(MAX($BD$6:$BD$1143)-MIN($BD$6:$BD$1143)))^2+(1-(BG6-MIN($BG$6:$BG$1143))/(MAX($BG$6:$BG$1143)-MIN($BG$6:$BG$1143)))^2) -> 0.76020916
A7: 1178 | B7: 10.1016/j.jallcom.2016.11.137 | C7: =_xlfn.XLOOKUP(A7,All!$A:$A,All!$C:$C,"") -> Cu-Al-Cr-Mg-Ni-Si | D7: 2 | E7: 质量分数 | F7: =100-SUM(G7:L7) -> 92.25 | G7: 0.5 | H7: 0.1 | I7: 0.15 | J7: 6 | K7: 1 | L7: 0 | M7: 摩尔分数 | N7: {=(F7/$F$4)/SUMPRODUCT($F7:$L7/$F$4:$L$4)*100} -> 89.824126 | O7: {=(G7/$G$4)/SUMPRODUCT($F7:$L7/$F$4:$L$4)*100} -> 1.1465968 | P7: {=(H7/$H$4)/SUMPRODUCT($F7:$L7/$F$4:$L$4)*100} -> 0.11899944 | Q7: {=(I7/$I$4)/SUMPRODUCT($F7:$L7/$F$4:$L$4)*100} -> 0.38186555 | R7: {=(J7/$J$4)/SUMPRODUCT($F7:$L7/$F$4:$L$4)*100} -> 6.3252805 | S7: {=(K7/$K$4)/SUMPRODUCT($F7:$L7/$F$4:$L$4)*100} -> 2.2031315 | T7: {=(L7/$L$4)/SUMPRODUCT($F7:$L7/$F$4:$L$4)*100} -> 0 | U7: =SUM(N7:T7) -> 100 | V7: =IF(K7<>0,J7/(K7),0) -> 6 | W7: =J7+K7 -> 7 | X7: =J7*K7 -> 6 | Y7: =IF(J7+K7<>0,I7/(J7+K7),0) -> 0.021428571 | Z7: =IF(J7+K7<>0,L7/(J7+K7),0) -> 0 | AA7: =IF(L7<>0,H7/(L7),0) -> 0 | AB7: =H7+L7 -> 0.1 | AC7: =H7*L7 -> 0 | AD7: =IF(H7<>0,P7/(H7),0) -> 1.1899944 | AE7: =IF(J7+K7<>0,H7/(J7+K7),0) -> 0.014285714 | AF7: =IF(H7<>0,(J7+K7)/(H7),0) -> 70 | AG7: =(J7+K7)*H7 -> 0.7 | AH7: =(100-N7)% -> 0.10175874 | AI7: {=SQRT(SUMPRODUCT(N7:T7/100,(1-($N$4:$T$4/(SUMPRODUCT(N7:T7,$N$4:$T$4)/100)))^2))} -> 0.029053738 | AJ7: {=SUMPRODUCT(N7:T7,$N$3:$T$3)/100} -> 1.8947688 | AK7: {=SUMPRODUCT(N7:T7/100,($N$3:$T$3-(SUMPRODUCT(N7:T7,$N$3:$T$3)/100))^2)} -> 0.0023410653 | AL7: {=SUMPRODUCT(N7:T7/100,($N$2:$T$2-(SUMPRODUCT(N7:T7,$N$2:$T$2)/100))^2)} -> 2.0935075 | AM7: {=SUMPRODUCT(N7:T7,$N$2:$T$2)/100} -> 10.650482 | AN7: {=SUMPRODUCT(N7:T7,$N$1:$T$1)/100} -> 1109.7582 | AO7: {=-8.314*SUMPRODUCT((N7:T7/100)*LN(N7:T7/100+0.000000000001))} -> 3.6213944 | AP7: {=SUMPRODUCT((N7:T7/100)^2)} -> 0.81147113 | AQ7: {=1/SUMPRODUCT((N7:T7/100)^2)} -> 1.2323297 | AR7: Solution ==> Quenching ==> Deformation ==> Aging ==> Secondary TMP ==> Secondary Aging | AS7: =IF(AR7="Solution ==> Quenching ==> Deformation ==> Aging ==> Secondary TMP ==> Secondary Aging",2,IF(AR7="Solution ==> Quenching ==> Deformation ==> Aging",1,IF(AR7="Solution ==> Quenching ==> Aging",0,""))) -> 2 | AT7: 979.85 | AU7: 4 | AV7: 50 | AW7: 449.85 | AX7: 8 | AY7: =AV7%*AW7 -> 224.925 | AZ7: =AV7%*AX7 -> 4 | BA7: =AW7*AX7 -> 3598.8 | BB7: =AT7-AW7 -> 530 | BC7: Y | BD7: 145 | BE7: N/A | BF7: N/A | BG7: 63 | BH7: =IF(OR(BD7="",BG7=""),"",((BD7-AVERAGE($BD$6:$BD$1143))/_xlfn.STDEV.S($BD$6:$BD$1143))-$BJ$1*((AVERAGE($BG$6:$BG$1143)-BG7)/_xlfn.STDEV.S($BG$6:$BG$1143))) -> -0.85953506 | BI7: =SQRT((1-(BD7-MIN($BD$6:$BD$1143))/(MAX($BD$6:$BD$1143)-MIN($BD$6:$BD$1143)))^2+(1-(BG7-MIN($BG$6:$BG$1143))/(MAX($BG$6:$BG$1143)-MIN($BG$6:$BG$1143)))^2) -> 0.82335729
A8: 1177 | B8: 10.1016/j.jallcom.2016.11.137 | C8: =_xlfn.XLOOKUP(A8,All!$A:$A,All!$C:$C,"") -> Cu-Al-Cr-Mg-Ni-Si | D8: 2 | E8: 质量分数 | F8: =100-SUM(G8:L8) -> 92.25 | G8: 0.5 | H8: 0.1 | I8: 0.15 | J8: 6 | K8: 1 | L8: 0 | M8: 摩尔分数 | N8: {=(F8/$F$4)/SUMPRODUCT($F8:$L8/$F$4:$L$4)*100} -> 89.824126 | O8: {=(G8/$G$4)/SUMPRODUCT($F8:$L8/$F$4:$L$4)*100} -> 1.1465968 | P8: {=(H8/$H$4)/SUMPRODUCT($F8:$L8/$F$4:$L$4)*100} -> 0.11899944 | Q8: {=(I8/$I$4)/SUMPRODUCT($F8:$L8/$F$4:$L$4)*100} -> 0.38186555 | R8: {=(J8/$J$4)/SUMPRODUCT($F8:$L8/$F$4:$L$4)*100} -> 6.3252805 | S8: {=(K8/$K$4)/SUMPRODUCT($F8:$L8/$F$4:$L$4)*100} -> 2.2031315 | T8: {=(L8/$L$4)/SUMPRODUCT($F8:$L8/$F$4:$L$4)*100} -> 0 | U8: =SUM(N8:T8) -> 100 | V8: =IF(K8<>0,J8/(K8),0) -> 6 | W8: =J8+K8 -> 7 | X8: =J8*K8 -> 6 | Y8: =IF(J8+K8<>0,I8/(J8+K8),0) -> 0.021428571 | Z8: =IF(J8+K8<>0,L8/(J8+K8),0) -> 0 | AA8: =IF(L8<>0,H8/(L8),0) -> 0 | AB8: =H8+L8 -> 0.1 | AC8: =H8*L8 -> 0 | AD8: =IF(H8<>0,P8/(H8),0) -> 1.1899944 | AE8: =IF(J8+K8<>0,H8/(J8+K8),0) -> 0.014285714 | AF8: =IF(H8<>0,(J8+K8)/(H8),0) -> 70 | AG8: =(J8+K8)*H8 -> 0.7 | AH8: =(100-N8)% -> 0.10175874 | AI8: {=SQRT(SUMPRODUCT(N8:T8/100,(1-($N$4:$T$4/(SUMPRODUCT(N8:T8,$N$4:$T$4)/100)))^2))} -> 0.029053738 | AJ8: {=SUMPRODUCT(N8:T8,$N$3:$T$3)/100} -> 1.8947688 | AK8: {=SUMPRODUCT(N8:T8/100,($N$3:$T$3-(SUMPRODUCT(N8:T8,$N$3:$T$3)/100))^2)} -> 0.0023410653 | AL8: {=SUMPRODUCT(N8:T8/100,($N$2:$T$2-(SUMPRODUCT(N8:T8,$N$2:$T$2)/100))^2)} -> 2.0935075 | AM8: {=SUMPRODUCT(N8:T8,$N$2:$T$2)/100} -> 10.650482 | AN8: {=SUMPRODUCT(N8:T8,$N$1:$T$1)/100} -> 1109.7582 | AO8: {=-8.314*SUMPRODUCT((N8:T8/100)*LN(N8:T8/100+0.000000000001))} -> 3.6213944 | AP8: {=SUMPRODUCT((N8:T8/100)^2)} -> 0.81147113 | AQ8: {=1/SUMPRODUCT((N8:T8/100)^2)} -> 1.2323297 | AR8: Solution ==> Quenching ==> Deformation ==> Aging ==> Secondary TMP ==> Secondary Aging | AS8: =IF(AR8="Solution ==> Quenching ==> Deformation ==> Aging ==> Secondary TMP ==> Secondary Aging",2,IF(AR8="Solution ==> Quenching ==> Deformation ==> Aging",1,IF(AR8="Solution ==> Quenching ==> Aging",0,""))) -> 2 | AT8: 979.85 | AU8: 4 | AV8: 50 | AW8: 399.85 | AX8: 8 | AY8: =AV8%*AW8 -> 199.925 | AZ8: =AV8%*AX8 -> 4 | BA8: =AW8*AX8 -> 3198.8 | BB8: =AT8-AW8 -> 580 | BC8: Y | BD8: 184 | BE8: N/A | BF8: N/A | BG8: 63 | BH8: =IF(OR(BD8="",BG8=""),"",((BD8-AVERAGE($BD$6:$BD$1143))/_xlfn.STDEV.S($BD$6:$BD$1143))-$BJ$1*((AVERAGE($BG$6:$BG$1143)-BG8)/_xlfn.STDEV.S($BG$6:$BG$1143))) -> -0.35795899 | BI8: =SQRT((1-(BD8-MIN($BD$6:$BD$1143))/(MAX($BD$6:$BD$1143)-MIN($BD$6:$BD$1143)))^2+(1-(BG8-MIN($BG$6:$BG$1143))/(MAX($BG$6:$BG$1143)-MIN($BG$6:$BG$1143)))^2) -> 0.71787878
A9: 1174 | B9: 10.1016/j.jallcom.2016.11.137 | C9: =_xlfn.XLOOKUP(A9,All!$A:$A,All!$C:$C,"") -> Cu-Al-Cr-Mg-Ni-Si | D9: 2 | E9: 质量分数 | F9: =100-SUM(G9:L9) -> 92.25 | G9: 0.5 | H9: 0.1 | I9: 0.15 | J9: 6 | K9: 1 | L9: 0 | M9: 摩尔分数 | N9: {=(F9/$F$4)/SUMPRODUCT($F9:$L9/$F$4:$L$4)*100} -> 89.824126 | O9: {=(G9/$G$4)/SUMPRODUCT($F9:$L9/$F$4:$L$4)*100} -> 1.1465968 | P9: {=(H9/$H$4)/SUMPRODUCT($F9:$L9/$F$4:$L$4)*100} -> 0.11899944 | Q9: {=(I9/$I$4)/SUMPRODUCT($F9:$L9/$F$4:$L$4)*100} -> 0.38186555 | R9: {=(J9/$J$4)/SUMPRODUCT($F9:$L9/$F$4:$L$4)*100} -> 6.3252805 | S9: {=(K9/$K$4)/SUMPRODUCT($F9:$L9/$F$4:$L$4)*100} -> 2.2031315 | T9: {=(L9/$L$4)/SUMPRODUCT($F9:$L9/$F$4:$L$4)*100} -> 0 | U9: =SUM(N9:T9) -> 100 | V9: =IF(K9<>0,J9/(K9),0) -> 6 | W9: =J9+K9 -> 7 | X9: =J9*K9 -> 6 | Y9: =IF(J9+K9<>0,I9/(J9+K9),0) -> 0.021428571 | Z9: =IF(J9+K9<>0,L9/(J9+K9),0) -> 0 | AA9: =IF(L9<>0,H9/(L9),0) -> 0 | AB9: =H9+L9 -> 0.1 | AC9: =H9*L9 -> 0 | AD9: =IF(H9<>0,P9/(H9),0) -> 1.1899944 | AE9: =IF(J9+K9<>0,H9/(J9+K9),0) -> 0.014285714 | AF9: =IF(H9<>0,(J9+K9)/(H9),0) -> 70 | AG9: =(J9+K9)*H9 -> 0.7 | AH9: =(100-N9)% -> 0.10175874 | AI9: {=SQRT(SUMPRODUCT(N9:T9/100,(1-($N$4:$T$4/(SUMPRODUCT(N9:T9,$N$4:$T$4)/100)))^2))} -> 0.029053738 | AJ9: {=SUMPRODUCT(N9:T9,$N$3:$T$3)/100} -> 1.8947688 | AK9: {=SUMPRODUCT(N9:T9/100,($N$3:$T$3-(SUMPRODUCT(N9:T9,$N$3:$T$3)/100))^2)} -> 0.0023410653 | AL9: {=SUMPRODUCT(N9:T9/100,($N$2:$T$2-(SUMPRODUCT(N9:T9,$N$2:$T$2)/100))^2)} -> 2.0935075 | AM9: {=SUMPRODUCT(N9:T9,$N$2:$T$2)/100} -> 10.650482 | AN9: {=SUMPRODUCT(N9:T9,$N$1:$T$1)/100} -> 1109.7582 | AO9: {=-8.314*SUMPRODUCT((N9:T9/100)*LN(N9:T9/100+0.000000000001))} -> 3.6213944 | AP9: {=SUMPRODUCT((N9:T9/100)^2)} -> 0.81147113 | AQ9: {=1/SUMPRODUCT((N9:T9/100)^2)} -> 1.2323297 | AR9: Solution ==> Quenching ==> Deformation ==> Aging ==> Secondary TMP ==> Secondary Aging | AS9: =IF(AR9="Solution ==> Quenching ==> Deformation ==> Aging ==> Secondary TMP ==> Secondary Aging",2,IF(AR9="Solution ==> Quenching ==> Deformation ==> Aging",1,IF(AR9="Solution ==> Quenching ==> Aging",0,""))) -> 2 | AT9: 979.85 | AU9: 4 | AV9: 50 | AW9: 449.85 | AX9: 8 | AY9: =AV9%*AW9 -> 224.925 | AZ9: =AV9%*AX9 -> 4 | BA9: =AW9*AX9 -> 3598.8 | BB9: =AT9-AW9 -> 530 | BC9: Y | BD9: 148 | BE9: N/A | BF9: N/A | BG9: 62 | BH9: =IF(OR(BD9="",BG9=""),"",((BD9-AVERAGE($BD$6:$BD$1143))/_xlfn.STDEV.S($BD$6:$BD$1143))-$BJ$1*((AVERAGE($BG$6:$BG$1143)-BG9)/_xlfn.STDEV.S($BG$6:$BG$1143))) -> -0.82095229 | BI9: =SQRT((1-(BD9-MIN($BD$6:$BD$1143))/(MAX($BD$6:$BD$1143)-MIN($BD$6:$BD$1143)))^2+(1-(BG9-MIN($BG$6:$BG$1143))/(MAX($BG$6:$BG$1143)-MIN($BG$6:$BG$1143)))^2) -> 0.82074026
A10: 1150 | B10: 10.1016/j.jallcom.2016.11.137 | C10: =_xlfn.XLOOKUP(A10,All!$A:$A,All!$C:$C,"") -> Cu-Al-Cr-Mg-Ni-Si | D10: 2 | E10: 质量分数 | F10: =100-SUM(G10:L10) -> 92.25 | G10: 0.5 | H10: 0.1 | I10: 0.15 | J10: 6 | K10: 1 | L10: 0 | M10: 摩尔分数 | N10: {=(F10/$F$4)/SUMPRODUCT($F10:$L10/$F$4:$L$4)*100} -> 89.824126 | O10: {=(G10/$G$4)/SUMPRODUCT($F10:$L10/$F$4:$L$4)*100} -> 1.1465968 | P10: {=(H10/$H$4)/SUMPRODUCT($F10:$L10/$F$4:$L$4)*100} -> 0.11899944 | Q10: {=(I10/$I$4)/SUMPRODUCT($F10:$L10/$F$4:$L$4)*100} -> 0.38186555 | R10: {=(J10/$J$4)/SUMPRODUCT($F10:$L10/$F$4:$L$4)*100} -> 6.3252805 | S10: {=(K10/$K$4)/SUMPRODUCT($F10:$L10/$F$4:$L$4)*100} -> 2.2031315 | T10: {=(L10/$L$4)/SUMPRODUCT($F10:$L10/$F$4:$L$4)*100} -> 0 | U10: =SUM(N10:T10) -> 100 | V10: =IF(K10<>0,J10/(K10),0) -> 6 | W10: =J10+K10 -> 7 | X10: =J10*K10 -> 6 | Y10: =IF(J10+K10<>0,I10/(J10+K10),0) -> 0.021428571 | Z10: =IF(J10+K10<>0,L10/(J10+K10),0) -> 0 | AA10: =IF(L10<>0,H10/(L10),0) -> 0 | AB10: =H10+L10 -> 0.1 | AC10: =H10*L10 -> 0 | AD10: =IF(H10<>0,P10/(H10),0) -> 1.1899944 | AE10: =IF(J10+K10<>0,H10/(J10+K10),0) -> 0.014285714 | AF10: =IF(H10<>0,(J10+K10)/(H10),0) -> 70 | AG10: =(J10+K10)*H10 -> 0.7 | AH10: =(100-N10)% -> 0.10175874 | AI10: {=SQRT(SUMPRODUCT(N10:T10/100,(1-($N$4:$T$4/(SUMPRODUCT(N10:T10,$N$4:$T$4)/100)))^2))} -> 0.029053738 | AJ10: {=SUMPRODUCT(N10:T10,$N$3:$T$3)/100} -> 1.8947688 | AK10: {=SUMPRODUCT(N10:T10/100,($N$3:$T$3-(SUMPRODUCT(N10:T10,$N$3:$T$3)/100))^2)} -> 0.0023410653 | AL10: {=SUMPRODUCT(N10:T10/100,($N$2:$T$2-(SUMPRODUCT(N10:T10,$N$2:$T$2)/100))^2)} -> 2.0935075 | AM10: {=SUMPRODUCT(N10:T10,$N$2:$T$2)/100} -> 10.650482 | AN10: {=SUMPRODUCT(N10:T10,$N$1:$T$1)/100} -> 1109.7582 | AO10: {=-8.314*SUMPRODUCT((N10:T10/100)*LN(N10:T10/100+0.000000000001))} -> 3.6213944 | AP10: {=SUMPRODUCT((N10:T10/100)^2)} -> 0.81147113 | AQ10: {=1/SUMPRODUCT((N10:T10/100)^2)} -> 1.2323297 | AR10: Solution ==> Quenching ==> Deformation ==> Aging ==> Secondary TMP ==> Secondary Aging | AS10: =IF(AR10="Solution ==> Quenching ==> Deformation ==> Aging ==> Secondary TMP ==> Secondary Aging",2,IF(AR10="Solution ==> Quenching ==> Deformation ==> Aging",1,IF(AR10="Solution ==> Quenching ==> Aging",0,""))) -> 2 | AT10: 979.85 | AU10: 4 | AV10: 50 | AW10: 449.85 | AX10: 6 | AY10: =AV10%*AW10 -> 224.925 | AZ10: =AV10%*AX10 -> 3 | BA10: =AW10*AX10 -> 2699.1 | BB10: =AT10-AW10 -> 530 | BC10: Y | BD10: 149 | BE10: N/A | BF10: N/A | BG10: 62 | BH10: =IF(OR(BD10="",BG10=""),"",((BD10-AVERAGE($BD$6:$BD$1143))/_xlfn.STDEV.S($BD$6:$BD$1143))-$BJ$1*((AVERAGE($BG$6:$BG$1143)-BG10)/_xlfn.STDEV.S($BG$6:$BG$1143))) -> -0.80809136 | BI10: =SQRT((1-(BD10-MIN($BD$6:$BD$1143))/(MAX($BD$6:$BD$1143)-MIN($BD$6:$BD$1143)))^2+(1-(BG10-MIN($BG$6:$BG$1143))/(MAX($BG$6:$BG$1143)-MIN($BG$6:$BG$1143)))^2) -> 0.81801288
A11: 1122 | B11: 10.1016/j.jallcom.2016.11.137 | C11: =_xlfn.XLOOKUP(A11,All!$A:$A,All!$C:$C,"") -> Cu-Al-Cr-Mg-Ni-Si | D11: 2 | E11: 质量分数 | F11: =100-SUM(G11:L11) -> 92.25 | G11: 0.5 | H11: 0.1 | I11: 0.15 | J11: 6 | K11: 1 | L11: 0 | M11: 摩尔分数 | N11: {=(F11/$F$4)/SUMPRODUCT($F11:$L11/$F$4:$L$4)*100} -> 89.824126 | O11: {=(G11/$G$4)/SUMPRODUCT($F11:$L11/$F$4:$L$4)*100} -> 1.1465968 | P11: {=(H11/$H$4)/SUMPRODUCT($F11:$L11/$F$4:$L$4)*100} -> 0.11899944 | Q11: {=(I11/$I$4)/SUMPRODUCT($F11:$L11/$F$4:$L$4)*100} -> 0.38186555 | R11: {=(J11/$J$4)/SUMPRODUCT($F11:$L11/$F$4:$L$4)*100} -> 6.3252805 | S11: {=(K11/$K$4)/SUMPRODUCT($F11:$L11/$F$4:$L$4)*100} -> 2.2031315 | T11: {=(L11/$L$4)/SUMPRODUCT($F11:$L11/$F$4:$L$4)*100} -> 0 | U11: =SUM(N11:T11) -> 100 | V11: =IF(K11<>0,J11/(K11),0) -> 6 | W11: =J11+K11 -> 7 | X11: =J11*K11 -> 6 | Y11: =IF(J11+K11<>0,I11/(J11+K11),0) -> 0.021428571 | Z11: =IF(J11+K11<>0,L11/(J11+K11),0) -> 0 | AA11: =IF(L11<>0,H11/(L11),0) -> 0 | AB11: =H11+L11 -> 0.1 | AC11: =H11*L11 -> 0 | AD11: =IF(H11<>0,P11/(H11),0) -> 1.1899944 | AE11: =IF(J11+K11<>0,H11/(J11+K11),0) -> 0.014285714 | AF11: =IF(H11<>0,(J11+K11)/(H11),0) -> 70 | AG11: =(J11+K11)*H11 -> 0.7 | AH11: =(100-N11)% -> 0.10175874 | AI11: {=SQRT(SUMPRODUCT(N11:T11/100,(1-($N$4:$T$4/(SUMPRODUCT(N11:T11,$N$4:$T$4)/100)))^2))} -> 0.029053738 | AJ11: {=SUMPRODUCT(N11:T11,$N$3:$T$3)/100} -> 1.8947688 | AK11: {=SUMPRODUCT(N11:T11/100,($N$3:$T$3-(SUMPRODUCT(N11:T11,$N$3:$T$3)/100))^2)} -> 0.0023410653 | AL11: {=SUMPRODUCT(N11:T11/100,($N$2:$T$2-(SUMPRODUCT(N11:T11,$N$2:$T$2)/100))^2)} -> 2.0935075 | AM11: {=SUMPRODUCT(N11:T11,$N$2:$T$2)/100} -> 10.650482 | AN11: {=SUMPRODUCT(N11:T11,$N$1:$T$1)/100} -> 1109.7582 | AO11: {=-8.314*SUMPRODUCT((N11:T11/100)*LN(N11:T11/100+0.000000000001))} -> 3.6213944 | AP11: {=SUMPRODUCT((N11:T11/100)^2)} -> 0.81147113 | AQ11: {=1/SUMPRODUCT((N11:T11/100)^2)} -> 1.2323297 | AR11: Solution ==> Quenching ==> Deformation ==> Aging ==> Secondary TMP ==> Secondary Aging | AS11: =IF(AR11="Solution ==> Quenching ==> Deformation ==> Aging ==> Secondary TMP ==> Secondary Aging",2,IF(AR11="Solution ==> Quenching ==> Deformation ==> Aging",1,IF(AR11="Solution ==> Quenching ==> Aging",0,""))) -> 2 | AT11: 979.85 | AU11: 4 | AV11: 50 | AW11: 449.85 | AX11: 5 | AY11: =AV11%*AW11 -> 224.925 | AZ11: =AV11%*AX11 -> 2.5 | BA11: =AW11*AX11 -> 2249.25 | BB11: =AT11-AW11 -> 530 | BC11: Y | BD11: 154 | BE11: N/A | BF11: N/A | BG11: 62 | BH11: =IF(OR(BD11="",BG11=""),"",((BD11-AVERAGE($BD$6:$BD$1143))/_xlfn.STDEV.S($BD$6:$BD$1143))-$BJ$1*((AVERAGE($BG$6:$BG$1143)-BG11)/_xlfn.STDEV.S($BG$6:$BG$1143))) -> -0.74378674 | BI11: =SQRT((1-(BD11-MIN($BD$6:$BD$1143))/(MAX($BD$6:$BD$1143)-MIN($BD$6:$BD$1143)))^2+(1-(BG11-MIN($BG$6:$BG$1143))/(MAX($BG$6:$BG$1143)-MIN($BG$6:$BG$1143)))^2) -> 0.80441276
A12: 1145 | B12: 10.1016/j.jallcom.2016.11.137 | C12: =_xlfn.XLOOKUP(A12,All!$A:$A,All!$C:$C,"") -> Cu-Al-Cr-Mg-Ni-Si | D12: 2 | E12: 质量分数 | F12: =100-SUM(G12:L12) -> 92.25 | G12: 0.5 | H12: 0.1 | I12: 0.15 | J12: 6 | K12: 1 | L12: 0 | M12: 摩尔分数 | N12: {=(F12/$F$4)/SUMPRODUCT($F12:$L12/$F$4:$L$4)*100} -> 89.824126 | O12: {=(G12/$G$4)/SUMPRODUCT($F12:$L12/$F$4:$L$4)*100} -> 1.1465968 | P12: {=(H12/$H$4)/SUMPRODUCT($F12:$L12/$F$4:$L$4)*100} -> 0.11899944 | Q12: {=(I12/$I$4)/SUMPRODUCT($F12:$L12/$F$4:$L$4)*100} -> 0.38186555 | R12: {=(J12/$J$4)/SUMPRODUCT($F12:$L12/$F$4:$L$4)*100} -> 6.3252805 | S12: {=(K12/$K$4)/SUMPRODUCT($F12:$L12/$F$4:$L$4)*100} -> 2.2031315 | T12: {=(L12/$L$4)/SUMPRODUCT($F12:$L12/$F$4:$L$4)*100} -> 0 | U12: =SUM(N12:T12) -> 100 | V12: =IF(K12<>0,J12/(K12),0) -> 6 | W12: =J12+K12 -> 7 | X12: =J12*K12 -> 6 | Y12: =IF(J12+K12<>0,I12/(J12+K12),0) -> 0.021428571 | Z12: =IF(J12+K12<>0,L12/(J12+K12),0) -> 0 | AA12: =IF(L12<>0,H12/(L12),0) -> 0 | AB12: =H12+L12 -> 0.1 | AC12: =H12*L12 -> 0 | AD12: =IF(H12<>0,P12/(H12),0) -> 1.1899944 | AE12: =IF(J12+K12<>0,H12/(J12+K12),0) -> 0.014285714 | AF12: =IF(H12<>0,(J12+K12)/(H12),0) -> 70 | AG12: =(J12+K12)*H12 -> 0.7 | AH12: =(100-N12)% -> 0.10175874 | AI12: {=SQRT(SUMPRODUCT(N12:T12/100,(1-($N$4:$T$4/(SUMPRODUCT(N12:T12,$N$4:$T$4)/100)))^2))} -> 0.029053738 | AJ12: {=SUMPRODUCT(N12:T12,$N$3:$T$3)/100} -> 1.8947688 | AK12: {=SUMPRODUCT(N12:T12/100,($N$3:$T$3-(SUMPRODUCT(N12:T12,$N$3:$T$3)/100))^2)} -> 0.0023410653 | AL12: {=SUMPRODUCT(N12:T12/100,($N$2:$T$2-(SUMPRODUCT(N12:T12,$N$2:$T$2)/100))^2)} -> 2.0935075 | AM12: {=SUMPRODUCT(N12:T12,$N$2:$T$2)/100} -> 10.650482 | AN12: {=SUMPRODUCT(N12:T12,$N$1:$T$1)/100} -> 1109.7582 | AO12: {=-8.314*SUMPRODUCT((N12:T12/100)*LN(N12:T12/100+0.000000000001))} -> 3.6213944 | AP12: {=SUMPRODUCT((N12:T12/100)^2)} -> 0.81147113 | AQ12: {=1/SUMPRODUCT((N12:T12/100)^2)} -> 1.2323297 | AR12: Solution ==> Quenching ==> Deformation ==> Aging ==> Secondary TMP ==> Secondary Aging | AS12: =IF(AR12="Solution ==> Quenching ==> Deformation ==> Aging ==> Secondary TMP ==> Secondary Aging",2,IF(AR12="Solution ==> Quenching ==> Deformation ==> Aging",1,IF(AR12="Solution ==> Quenching ==> Aging",0,""))) -> 2 | AT12: 979.85 | AU12: 4 | AV12: 50 | AW12: 399.85 | AX12: 6 | AY12: =AV12%*AW12 -> 199.925 | AZ12: =AV12%*AX12 -> 3 | BA12: =AW12*AX12 -> 2399.1 | BB12: =AT12-AW12 -> 580 | BC12: Y | BD12: 168 | BE12: N/A | BF12: N/A | BG12: 62 | BH12: =IF(OR(BD12="",BG12=""),"",((BD12-AVERAGE($BD$6:$BD$1143))/_xlfn.STDEV.S($BD$6:$BD$1143))-$BJ$1*((AVERAGE($BG$6:$BG$1143)-BG12)/_xlfn.STDEV.S($BG$6:$BG$1143))) -> -0.56373379 | BI12: =SQRT((1-(BD12-MIN($BD$6:$BD$1143))/(MAX($BD$6:$BD$1143)-MIN($BD$6:$BD$1143)))^2+(1-(BG12-MIN($BG$6:$BG$1143))/(MAX($BG$6:$BG$1143)-MIN($BG$6:$BG$1143)))^2) -> 0.76668134
A13: 1117 | B13: 10.1016/j.jallcom.2016.11.137 | C13: =_xlfn.XLOOKUP(A13,All!$A:$A,All!$C:$C,"") -> Cu-Al-Cr-Mg-Ni-Si | D13: 2 | E13: 质量分数 | F13: =100-SUM(G13:L13) -> 92.25 | G13: 0.5 | H13: 0.1 | I13: 0.15 | J13: 6 | K13: 1 | L13: 0 | M13: 摩尔分数 | N13: {=(F13/$F$4)/SUMPRODUCT($F13:$L13/$F$4:$L$4)*100} -> 89.824126 | O13: {=(G13/$G$4)/SUMPRODUCT($F13:$L13/$F$4:$L$4)*100} -> 1.1465968 | P13: {=(H13/$H$4)/SUMPRODUCT($F13:$L13/$F$4:$L$4)*100} -> 0.11899944 | Q13: {=(I13/$I$4)/SUMPRODUCT($F13:$L13/$F$4:$L$4)*100} -> 0.38186555 | R13: {=(J13/$J$4)/SUMPRODUCT($F13:$L13/$F$4:$L$4)*100} -> 6.3252805 | S13: {=(K13/$K$4)/SUMPRODUCT($F13:$L13/$F$4:$L$4)*100} -> 2.2031315 | T13: {=(L13/$L$4)/SUMPRODUCT($F13:$L13/$F$4:$L$4)*100} -> 0 | U13: =SUM(N13:T13) -> 100 | V13: =IF(K13<>0,J13/(K13),0) -> 6 | W13: =J13+K13 -> 7 | X13: =J13*K13 -> 6 | Y13: =IF(J13+K13<>0,I13/(J13+K13),0) -> 0.021428571 | Z13: =IF(J13+K13<>0,L13/(J13+K13),0) -> 0 | AA13: =IF(L13<>0,H13/(L13),0) -> 0 | AB13: =H13+L13 -> 0.1 | AC13: =H13*L13 -> 0 | AD13: =IF(H13<>0,P13/(H13),0) -> 1.1899944 | AE13: =IF(J13+K13<>0,H13/(J13+K13),0) -> 0.014285714 | AF13: =IF(H13<>0,(J13+K13)/(H13),0) -> 70 | AG13: =(J13+K13)*H13 -> 0.7 | AH13: =(100-N13)% -> 0.10175874 | AI13: {=SQRT(SUMPRODUCT(N13:T13/100,(1-($N$4:$T$4/(SUMPRODUCT(N13:T13,$N$4:$T$4)/100)))^2))} -> 0.029053738 | AJ13: {=SUMPRODUCT(N13:T13,$N$3:$T$3)/100} -> 1.8947688 | AK13: {=SUMPRODUCT(N13:T13/100,($N$3:$T$3-(SUMPRODUCT(N13:T13,$N$3:$T$3)/100))^2)} -> 0.0023410653 | AL13: {=SUMPRODUCT(N13:T13/100,($N$2:$T$2-(SUMPRODUCT(N13:T13,$N$2:$T$2)/100))^2)} -> 2.0935075 | AM13: {=SUMPRODUCT(N13:T13,$N$2:$T$2)/100} -> 10.650482 | AN13: {=SUMPRODUCT(N13:T13,$N$1:$T$1)/100} -> 1109.7582 | AO13: {=-8.314*SUMPRODUCT((N13:T13/100)*LN(N13:T13/100+0.000000000001))} -> 3.6213944 | AP13: {=SUMPRODUCT((N13:T13/100)^2)} -> 0.81147113 | AQ13: {=1/SUMPRODUCT((N13:T13/100)^2)} -> 1.2323297 | AR13: Solution ==> Quenching ==> Deformation ==> Aging ==> Secondary TMP ==> Secondary Aging | AS13: =IF(AR13="Solution ==> Quenching ==> Deformation ==> Aging ==> Secondary TMP ==> Secondary Aging",2,IF(AR13="Solution ==> Quenching ==> Deformation ==> Aging",1,IF(AR13="Solution ==> Quenching ==> Aging",0,""))) -> 2 | AT13: 979.85 | AU13: 4 | AV13: 50 | AW13: 399.85 | AX13: 5 | AY13: =AV13%*AW13 -> 199.925 | AZ13: =AV13%*AX13 -> 2.5 | BA13: =AW13*AX13 -> 1999.25 | BB13: =AT13-AW13 -> 580 | BC13: Y | BD13: 175 | BE13: N/A | BF13: N/A | BG13: 62 | BH13: =IF(OR(BD13="",BG13=""),"",((BD13-AVERAGE($BD$6:$BD$1143))/_xlfn.STDEV.S($BD$6:$BD$1143))-$BJ$1*((AVERAGE($BG$6:$BG$1143)-BG13)/_xlfn.STDEV.S($BG$6:$BG$1143))) -> -0.47370731 | BI13: =SQRT((1-(BD13-MIN($BD$6:$BD$1143))/(MAX($BD$6:$BD$1143)-MIN($BD$6:$BD$1143)))^2+(1-(BG13-MIN($BG$6:$BG$1143))/(MAX($BG$6:$BG$1143)-MIN($BG$6:$BG$1143)))^2) -> 0.74802651
A14: 1170 | B14: 10.1016/j.jallcom.2016.11.137 | C14: =_xlfn.XLOOKUP(A14,All!$A:$A,All!$C:$C,"") -> Cu-Al-Cr-Mg-Ni-Si | D14: 2 | E14: 质量分数 | F14: =100-SUM(G14:L14) -> 92.25 | G14: 0.5 | H14: 0.1 | I14: 0.15 | J14: 6 | K14: 1 | L14: 0 | M14: 摩尔分数 | N14: {=(F14/$F$4)/SUMPRODUCT($F14:$L14/$F$4:$L$4)*100} -> 89.824126 | O14: {=(G14/$G$4)/SUMPRODUCT($F14:$L14/$F$4:$L$4)*100} -> 1.1465968 | P14: {=(H14/$H$4)/SUMPRODUCT($F14:$L14/$F$4:$L$4)*100} -> 0.11899944 | Q14: {=(I14/$I$4)/SUMPRODUCT($F14:$L14/$F$4:$L$4)*100} -> 0.38186555 | R14: {=(J14/$J$4)/SUMPRODUCT($F14:$L14/$F$4:$L$4)*100} -> 6.3252805 | S14: {=(K14/$K$4)/SUMPRODUCT($F14:$L14/$F$4:$L$4)*100} -> 2.2031315 | T14: {=(L14/$L$4)/SUMPRODUCT($F14:$L14/$F$4:$L$4)*100} -> 0 | U14: =SUM(N14:T14) -> 100 | V14: =IF(K14<>0,J14/(K14),0) -> 6 | W14: =J14+K14 -> 7 | X14: =J14*K14 -> 6 | Y14: =IF(J14+K14<>0,I14/(J14+K14),0) -> 0.021428571 | Z14: =IF(J14+K14<>0,L14/(J14+K14),0) -> 0 | AA14: =IF(L14<>0,H14/(L14),0) -> 0 | AB14: =H14+L14 -> 0.1 | AC14: =H14*L14 -> 0 | AD14: =IF(H14<>0,P14/(H14),0) -> 1.1899944 | AE14: =IF(J14+K14<>0,H14/(J14+K14),0) -> 0.014285714 | AF14: =IF(H14<>0,(J14+K14)/(H14),0) -> 70 | AG14: =(J14+K14)*H14 -> 0.7 | AH14: =(100-N14)% -> 0.10175874 | AI14: {=SQRT(SUMPRODUCT(N14:T14/100,(1-($N$4:$T$4/(SUMPRODUCT(N14:T14,$N$4:$T$4)/100)))^2))} -> 0.029053738 | AJ14: {=SUMPRODUCT(N14:T14,$N$3:$T$3)/100} -> 1.8947688 | AK14: {=SUMPRODUCT(N14:T14/100,($N$3:$T$3-(SUMPRODUCT(N14:T14,$N$3:$T$3)/100))^2)} -> 0.0023410653 | AL14: {=SUMPRODUCT(N14:T14/100,($N$2:$T$2-(SUMPRODUCT(N14:T14,$N$2:$T$2)/100))^2)} -> 2.0935075 | AM14: {=SUMPRODUCT(N14:T14,$N$2:$T$2)/100} -> 10.650482 | AN14: {=SUMPRODUCT(N14:T14,$N$1:$T$1)/100} -> 1109.7582 | AO14: {=-8.314*SUMPRODUCT((N14:T14/100)*LN(N14:T14/100+0.000000000001))} -> 3.6213944 | AP14: {=SUMPRODUCT((N14:T14/100)^2)} -> 0.81147113 | AQ14: {=1/SUMPRODUCT((N14:T14/100)^2)} -> 1.2323297 | AR14: Solution ==> Quenching ==> Deformation ==> Aging ==> Secondary TMP ==> Secondary Aging | AS14: =IF(AR14="Solution ==> Quenching ==> Deformation ==> Aging ==> Secondary TMP ==> Secondary Aging",2,IF(AR14="Solution ==> Quenching ==> Deformation ==> Aging",1,IF(AR14="Solution ==> Quenching ==> Aging",0,""))) -> 2 | AT14: 979.85 | AU14: 4 | AV14: 50 | AW14: 449.85 | AX14: 8 | AY14: =AV14%*AW14 -> 224.925 | AZ14: =AV14%*AX14 -> 4 | BA14: =AW14*AX14 -> 3598.8 | BB14: =AT14-AW14 -> 530 | BC14: Y | BD14: 148 | BE14: N/A | BF14: N/A | BG14: 61 | BH14: =IF(OR(BD14="",BG14=""),"",((BD14-AVERAGE($BD$6:$BD$1143))/_xlfn.STDEV.S($BD$6:$BD$1143))-$BJ$1*((AVERAGE($BG$6:$BG$1143)-BG14)/_xlfn.STDEV.S($BG$6:$BG$1143))) -> -0.82095229 | BI14: =SQRT((1-(BD14-MIN($BD$6:$BD$1143))/(MAX($BD$6:$BD$1143)-MIN($BD$6:$BD$1143)))^2+(1-(BG14-MIN($BG$6:$BG$1143))/(MAX($BG$6:$BG$1143)-MIN($BG$6:$BG$1143)))^2) -> 0.82652636
A15: 1146 | B15: 10.1016/j.jallcom.2016.11.137 | C15: =_xlfn.XLOOKUP(A15,All!$A:$A,All!$C:$C,"") -> Cu-Al-Cr-Mg-Ni-Si | D15: 2 | E15: 质量分数 | F15: =100-SUM(G15:L15) -> 92.25 | G15: 0.5 | H15: 0.1 | I15: 0.15 | J15: 6 | K15: 1 | L15: 0 | M15: 摩尔分数 | N15: {=(F15/$F$4)/SUMPRODUCT($F15:$L15/$F$4:$L$4)*100} -> 89.824126 | O15: {=(G15/$G$4)/SUMPRODUCT($F15:$L15/$F$4:$L$4)*100} -> 1.1465968 | P15: {=(H15/$H$4)/SUMPRODUCT($F15:$L15/$F$4:$L$4)*100} -> 0.11899944 | Q15: {=(I15/$I$4)/SUMPRODUCT($F15:$L15/$F$4:$L$4)*100} -> 0.38186555 | R15: {=(J15/$J$4)/SUMPRODUCT($F15:$L15/$F$4:$L$4)*100} -> 6.3252805 | S15: {=(K15/$K$4)/SUMPRODUCT($F15:$L15/$F$4:$L$4)*100} -> 2.2031315 | T15: {=(L15/$L$4)/SUMPRODUCT($F15:$L15/$F$4:$L$4)*100} -> 0 | U15: =SUM(N15:T15) -> 100 | V15: =IF(K15<>0,J15/(K15),0) -> 6 | W15: =J15+K15 -> 7 | X15: =J15*K15 -> 6 | Y15: =IF(J15+K15<>0,I15/(J15+K15),0) -> 0.021428571 | Z15: =IF(J15+K15<>0,L15/(J15+K15),0) -> 0 | AA15: =IF(L15<>0,H15/(L15),0) -> 0 | AB15: =H15+L15 -> 0.1 | AC15: =H15*L15 -> 0 | AD15: =IF(H15<>0,P15/(H15),0) -> 1.1899944 | AE15: =IF(J15+K15<>0,H15/(J15+K15),0) -> 0.014285714 | AF15: =IF(H15<>0,(J15+K15)/(H15),0) -> 70 | AG15: =(J15+K15)*H15 -> 0.7 | AH15: =(100-N15)% -> 0.10175874 | AI15: {=SQRT(SUMPRODUCT(N15:T15/100,(1-($N$4:$T$4/(SUMPRODUCT(N15:T15,$N$4:$T$4)/100)))^2))} -> 0.029053738 | AJ15: {=SUMPRODUCT(N15:T15,$N$3:$T$3)/100} -> 1.8947688 | AK15: {=SUMPRODUCT(N15:T15/100,($N$3:$T$3-(SUMPRODUCT(N15:T15,$N$3:$T$3)/100))^2)} -> 0.0023410653 | AL15: {=SUMPRODUCT(N15:T15/100,($N$2:$T$2-(SUMPRODUCT(N15:T15,$N$2:$T$2)/100))^2)} -> 2.0935075 | AM15: {=SUMPRODUCT(N15:T15,$N$2:$T$2)/100} -> 10.650482 | AN15: {=SUMPRODUCT(N15:T15,$N$1:$T$1)/100} -> 1109.7582 | AO15: {=-8.314*SUMPRODUCT((N15:T15/100)*LN(N15:T15/100+0.000000000001))} -> 3.6213944 | AP15: {=SUMPRODUCT((N15:T15/100)^2)} -> 0.81147113 | AQ15: {=1/SUMPRODUCT((N15:T15/100)^2)} -> 1.2323297 | AR15: Solution ==> Quenching ==> Deformation ==> Aging ==> Secondary TMP ==> Secondary Aging | AS15: =IF(AR15="Solution ==> Quenching ==> Deformation ==> Aging ==> Secondary TMP ==> Secondary Aging",2,IF(AR15="Solution ==> Quenching ==> Deformation ==> Aging",1,IF(AR15="Solution ==> Quenching ==> Aging",0,""))) -> 2 | AT15: 979.85 | AU15: 4 | AV15: 50 | AW15: 449.85 | AX15: 6 | AY15: =AV15%*AW15 -> 224.925 | AZ15: =AV15%*AX15 -> 3 | BA15: =AW15*AX15 -> 2699.1 | BB15: =AT15-AW15 -> 530 | BC15: Y | BD15: 150 | BE15: N/A | BF15: N/A | BG15: 61 | BH15: =IF(OR(BD15="",BG15=""),"",((BD15-AVERAGE($BD$6:$BD$1143))/_xlfn.STDEV.S($BD$6:$BD$1143))-$BJ$1*((AVERAGE($BG$6:$BG$1143)-BG15)/_xlfn.STDEV.S($BG$6:$BG$1143))) -> -0.79523044 | BI15: =SQRT((1-(BD15-MIN($BD$6:$BD$1143))/(MAX($BD$6:$BD$1143)-MIN($BD$6:$BD$1143)))^2+(1-(BG15-MIN($BG$6:$BG$1143))/(MAX($BG$6:$BG$1143)-MIN($BG$6:$BG$1143)))^2) -> 0.82111245
A16: 1091 | B16: 10.1016/j.jallcom.2016.11.137 | C16: =_xlfn.XLOOKUP(A16,All!$A:$A,All!$C:$C,"") -> Cu-Al-Cr-Mg-Ni-Si | D16: 2 | E16: 质量分数 | F16: =100-SUM(G16:L16) -> 92.25 | G16: 0.5 | H16: 0.1 | I16: 0.15 | J16: 6 | K16: 1 | L16: 0 | M16: 摩尔分数 | N16: {=(F16/$F$4)/SUMPRODUCT($F16:$L16/$F$4:$L$4)*100} -> 89.824126 | O16: {=(G16/$G$4)/SUMPRODUCT($F16:$L16/$F$4:$L$4)*100} -> 1.1465968 | P16: {=(H16/$H$4)/SUMPRODUCT($F16:$L16/$F$4:$L$4)*100} -> 0.11899944 | Q16: {=(I16/$I$4)/SUMPRODUCT($F16:$L16/$F$4:$L$4)*100} -> 0.38186555 | R16: {=(J16/$J$4)/SUMPRODUCT($F16:$L16/$F$4:$L$4)*100} -> 6.3252805 | S16: {=(K16/$K$4)/SUMPRODUCT($F16:$L16/$F$4:$L$4)*100} -> 2.2031315 | T16: {=(L16/$L$4)/SUMPRODUCT($F16:$L16/$F$4:$L$4)*100} -> 0 | U16: =SUM(N16:T16) -> 100 | V16: =IF(K16<>0,J16/(K16),0) -> 6 | W16: =J16+K16 -> 7 | X16: =J16*K16 -> 6 | Y16: =IF(J16+K16<>0,I16/(J16+K16),0) -> 0.021428571 | Z16: =IF(J16+K16<>0,L16/(J16+K16),0) -> 0 | AA16: =IF(L16<>0,H16/(L16),0) -> 0 | AB16: =H16+L16 -> 0.1 | AC16: =H16*L16 -> 0 | AD16: =IF(H16<>0,P16/(H16),0) -> 1.1899944 | AE16: =IF(J16+K16<>0,H16/(J16+K16),0) -> 0.014285714 | AF16: =IF(H16<>0,(J16+K16)/(H16),0) -> 70 | AG16: =(J16+K16)*H16 -> 0.7 | AH16: =(100-N16)% -> 0.10175874 | AI16: {=SQRT(SUMPRODUCT(N16:T16/100,(1-($N$4:$T$4/(SUMPRODUCT(N16:T16,$N$4:$T$4)/100)))^2))} -> 0.029053738 | AJ16: {=SUMPRODUCT(N16:T16,$N$3:$T$3)/100} -> 1.8947688 | AK16: {=SUMPRODUCT(N16:T16/100,($N$3:$T$3-(SUMPRODUCT(N16:T16,$N$3:$T$3)/100))^2)} -> 0.0023410653 | AL16: {=SUMPRODUCT(N16:T16/100,($N$2:$T$2-(SUMPRODUCT(N16:T16,$N$2:$T$2)/100))^2)} -> 2.0935075 | AM16: {=SUMPRODUCT(N16:T16,$N$2:$T$2)/100} -> 10.650482 | AN16: {=SUMPRODUCT(N16:T16,$N$1:$T$1)/100} -> 1109.7582 | AO16: {=-8.314*SUMPRODUCT((N16:T16/100)*LN(N16:T16/100+0.000000000001))} -> 3.6213944 | AP16: {=SUMPRODUCT((N16:T16/100)^2)} -> 0.81147113 | AQ16: {=1/SUMPRODUCT((N16:T16/100)^2)} -> 1.2323297 | AR16: Solution ==> Quenching ==> Deformation ==> Aging ==> Secondary TMP ==> Secondary Aging | AS16: =IF(AR16="Solution ==> Quenching ==> Deformation ==> Aging ==> Secondary TMP ==> Secondary Aging",2,IF(AR16="Solution ==> Quenching ==> Deformation ==> Aging",1,IF(AR16="Solution ==> Quenching ==> Aging",0,""))) -> 2 | AT16: 979.85 | AU16: 4 | AV16: 50 | AW16: 449.85 | AX16: 4 | AY16: =AV16%*AW16 -> 224.925 | AZ16: =AV16%*AX16 -> 2 | BA16: =AW16*AX16 -> 1799.4 | BB16: =AT16-AW16 -> 530 | BC16: Y | BD16: 156 | BE16: N/A | BF16: N/A | BG16: 61 | BH16: =IF(OR(BD16="",BG16=""),"",((BD16-AVERAGE($BD$6:$BD$1143))/_xlfn.STDEV.S($BD$6:$BD$1143))-$BJ$1*((AVERAGE($BG$6:$BG$1143)-BG16)/_xlfn.STDEV.S($BG$6:$BG$1143))) -> -0.71806489 | BI16: =SQRT((1-(BD16-MIN($BD$6:$BD$1143))/(MAX($BD$6:$BD$1143)-MIN($BD$6:$BD$1143)))^2+(1-(BG16-MIN($BG$6:$BG$1143))/(MAX($BG$6:$BG$1143)-MIN($BG$6:$BG$1143)))^2) -> 0.80493279
A17: 1095 | B17: 10.1016/j.jallcom.2016.11.137 | C17: =_xlfn.XLOOKUP(A17,All!$A:$A,All!$C:$C,"") -> Cu-Al-Cr-Mg-Ni-Si | D17: 2 | E17: 质量分数 | F17: =100-SUM(G17:L17) -> 92.25 | G17: 0.5 | H17: 0.1 | I17: 0.15 | J17: 6 | K17: 1 | L17: 0 | M17: 摩尔分数 | N17: {=(F17/$F$4)/SUMPRODUCT($F17:$L17/$F$4:$L$4)*100} -> 89.824126 | O17: {=(G17/$G$4)/SUMPRODUCT($F17:$L17/$F$4:$L$4)*100} -> 1.1465968 | P17: {=(H17/$H$4)/SUMPRODUCT($F17:$L17/$F$4:$L$4)*100} -> 0.11899944 | Q17: {=(I17/$I$4)/SUMPRODUCT($F17:$L17/$F$4:$L$4)*100} -> 0.38186555 | R17: {=(J17/$J$4)/SUMPRODUCT($F17:$L17/$F$4:$L$4)*100} -> 6.3252805 | S17: {=(K17/$K$4)/SUMPRODUCT($F17:$L17/$F$4:$L$4)*100} -> 2.2031315 | T17: {=(L17/$L$4)/SUMPRODUCT($F17:$L17/$F$4:$L$4)*100} -> 0 | U17: =SUM(N17:T17) -> 100 | V17: =IF(K17<>0,J17/(K17),0) -> 6 | W17: =J17+K17 -> 7 | X17: =J17*K17 -> 6 | Y17: =IF(J17+K17<>0,I17/(J17+K17),0) -> 0.021428571 | Z17: =IF(J17+K17<>0,L17/(J17+K17),0) -> 0 | AA17: =IF(L17<>0,H17/(L17),0) -> 0 | AB17: =H17+L17 -> 0.1 | AC17: =H17*L17 -> 0 | AD17: =IF(H17<>0,P17/(H17),0) -> 1.1899944 | AE17: =IF(J17+K17<>0,H17/(J17+K17),0) -> 0.014285714 | AF17: =IF(H17<>0,(J17+K17)/(H17),0) -> 70 | AG17: =(J17+K17)*H17 -> 0.7 | AH17: =(100-N17)% -> 0.10175874 | AI17: {=SQRT(SUMPRODUCT(N17:T17/100,(1-($N$4:$T$4/(SUMPRODUCT(N17:T17,$N$4:$T$4)/100)))^2))} -> 0.029053738 | AJ17: {=SUMPRODUCT(N17:T17,$N$3:$T$3)/100} -> 1.8947688 | AK17: {=SUMPRODUCT(N17:T17/100,($N$3:$T$3-(SUMPRODUCT(N17:T17,$N$3:$T$3)/100))^2)} -> 0.0023410653 | AL17: {=SUMPRODUCT(N17:T17/100,($N$2:$T$2-(SUMPRODUCT(N17:T17,$N$2:$T$2)/100))^2)} -> 2.0935075 | AM17: {=SUMPRODUCT(N17:T17,$N$2:$T$2)/100} -> 10.650482 | AN17: {=SUMPRODUCT(N17:T17,$N$1:$T$1)/100} -> 1109.7582 | AO17: {=-8.314*SUMPRODUCT((N17:T17/100)*LN(N17:T17/100+0.000000000001))} -> 3.6213944 | AP17: {=SUMPRODUCT((N17:T17/100)^2)} -> 0.81147113 | AQ17: {=1/SUMPRODUCT((N17:T17/100)^2)} -> 1.2323297 | AR17: Solution ==> Quenching ==> Deformation ==> Aging ==> Secondary TMP ==> Secondary Aging | AS17: =IF(AR17="Solution ==> Quenching ==> Deformation ==> Aging ==> Secondary TMP ==> Secondary Aging",2,IF(AR17="Solution ==> Quenching ==> Deformation ==> Aging",1,IF(AR17="Solution ==> Quenching ==> Aging",0,""))) -> 2 | AT17: 979.85 | AU17: 4 | AV17: 50 | AW17: 449.85 | AX17: 4 | AY17: =AV17%*AW17 -> 224.925 | AZ17: =AV17%*AX17 -> 2 | BA17: =AW17*AX17 -> 1799.4 | BB17: =AT17-AW17 -> 530 | BC17: Y | BD17: 163 | BE17: N/A | BF17: N/A | BG17: 61 | BH17: =IF(OR(BD17="",BG17=""),"",((BD17-AVERAGE($BD$6:$BD$1143))/_xlfn.STDEV.S($BD$6:$BD$1143))-$BJ$1*((AVERAGE($BG$6:$BG$1143)-BG17)/_xlfn.STDEV.S($BG$6:$BG$1143))) -> -0.62803841 | BI17: =SQRT((1-(BD17-MIN($BD$6:$BD$1143))/(MAX($BD$6:$BD$1143)-MIN($BD$6:$BD$1143)))^2+(1-(BG17-MIN($BG$6:$BG$1143))/(MAX($BG$6:$BG$1143)-MIN($BG$6:$BG$1143)))^2) -> 0.78618026
... A798: 1224 | B798: 10.1016/j.matlet.2017.04.039 | C798: =_xlfn.XLOOKUP(A798,All!$A:$A,All!$C:$C,"") -> Cu-Cr-Zr | D798: 1 | E798: 质量分数 | F798: =100-SUM(G798:L798) -> 99.2 | G798: 0 | H798: 0.3 | I798: 0 | J798: 0 | K798: 0 | L798: 0.5 | M798: 摩尔分数 | N798: {=(F798/$F$4)/SUMPRODUCT($F798:$L798/$F$4:$L$4)*100} -> 99.284455 | O798: {=(G798/$G$4)/SUMPRODUCT($F798:$L798/$F$4:$L$4)*100} -> 0 | P798: {=(H798/$H$4)/SUMPRODUCT($F798:$L798/$F$4:$L$4)*100} -> 0.36695188 | Q798: {=(I798/$I$4)/SUMPRODUCT($F798:$L798/$F$4:$L$4)*100} -> 0 | R798: {=(J798/$J$4)/SUMPRODUCT($F798:$L798/$F$4:$L$4)*100} -> 0 | S798: {=(K798/$K$4)/SUMPRODUCT($F798:$L798/$F$4:$L$4)*100} -> 0 | T798: {=(L798/$L$4)/SUMPRODUCT($F798:$L798/$F$4:$L$4)*100} -> 0.34859303 | U798: =SUM(N798:T798) -> 100 | V798: =IF(K798<>0,J798/(K798),0) -> 0 | W798: =J798+K798 -> 0 | X798: =J798*K798 -> 0 | Y798: =IF(J798+K798<>0,I798/(J798+K798),0) -> 0 | Z798: =IF(J798+K798<>0,L798/(J798+K798),0) -> 0 | AA798: =IF(L798<>0,H798/(L798),0) -> 0.6 | AB798: =H798+L798 -> 0.8 | AC798: =H798*L798 -> 0.15 | AD798: =IF(H798<>0,P798/(H798),0) -> 1.2231729 | AE798: =IF(J798+K798<>0,H798/(J798+K798),0) -> 0 | AF798: =IF(H798<>0,(J798+K798)/(H798),0) -> 0 | AG798: =(J798+K798)*H798 -> 0 | AH798: =(100-N798)% -> 0.0071554491 | AI798: {=SQRT(SUMPRODUCT(N798:T798/100,(1-($N$4:$T$4/(SUMPRODUCT(N798:T798,$N$4:$T$4)/100)))^2))} -> 0.014721863 | AJ798: {=SUMPRODUCT(N798:T798,$N$3:$T$3)/100} -> 1.8971323 | AK798: {=SUMPRODUCT(N798:T798/100,($N$3:$T$3-(SUMPRODUCT(N798:T798,$N$3:$T$3)/100))^2)} -> 0.0013357195 | AL798: {=SUMPRODUCT(N798:T798/100,($N$2:$T$2-(SUMPRODUCT(N798:T798,$N$2:$T$2)/100))^2)} -> 0.26072107 | AM798: {=SUMPRODUCT(N798:T798,$N$2:$T$2)/100} -> 10.957251 | AN798: {=SUMPRODUCT(N798:T798,$N$1:$T$1)/100} -> 1090.3232 | AO798: {=-8.314*SUMPRODUCT((N798:T798/100)*LN(N798:T798/100+0.000000000001))} -> 0.3943686 | AP798: {=SUMPRODUCT((N798:T798/100)^2)} -> 0.98576592 | AQ798: {=1/SUMPRODUCT((N798:T798/100)^2)} -> 1.0144396 | AR798: Solution ==> Quenching ==> Aging | AS798: =IF(AR798="Solution ==> Quenching ==> Deformation ==> Aging ==> Secondary TMP ==> Secondary Aging",2,IF(AR798="Solution ==> Quenching ==> Deformation ==> Aging",1,IF(AR798="Solution ==> Quenching ==> Aging",0,""))) -> 0 | AT798: 999.85 | AU798: 1 | AV798: 0 | AW798: 349.85 | AX798: 1 | AY798: =AV798%*AW798 -> 0 | AZ798: =AV798%*AX798 -> 0 | BA798: =AW798*AX798 -> 349.85 | BB798: =AT798-AW798 -> 650 | BC798: N | BD798: 87 | BE798: N/A | BF798: N/A | BG798: 36 | BH798: =IF(OR(BD798="",BG798=""),"",((BD798-AVERAGE($BD$6:$BD$1143))/_xlfn.STDEV.S($BD$6:$BD$1143))-$BJ$1*((AVERAGE($BG$6:$BG$1143)-BG798)/_xlfn.STDEV.S($BG$6:$BG$1143))) -> -1.6054687 | BI798: =SQRT((1-(BD798-MIN($BD$6:$BD$1143))/(MAX($BD$6:$BD$1143)-MIN($BD$6:$BD$1143)))^2+(1-(BG798-MIN($BG$6:$BG$1143))/(MAX($BG$6:$BG$1143)-MIN($BG$6:$BG$1143)))^2) -> 1.153783
A799: Mat23858 | B799: 10.1016/j.msea.2016.10.087 | C799: =_xlfn.XLOOKUP(A799,All!$A:$A,All!$C:$C,"") -> Cu-Cr-Zr | D799: 1 | E799: 质量分数 | F799: =100-SUM(G799:L799) -> 98.9 | G799: 0 | H799: 1 | I799: 0 | J799: 0 | K799: 0 | L799: 0.1 | M799: 摩尔分数 | N799: {=(F799/$F$4)/SUMPRODUCT($F799:$L799/$F$4:$L$4)*100} -> 98.710681 | O799: {=(G799/$G$4)/SUMPRODUCT($F799:$L799/$F$4:$L$4)*100} -> 0 | P799: {=(H799/$H$4)/SUMPRODUCT($F799:$L799/$F$4:$L$4)*100} -> 1.219793 | Q799: {=(I799/$I$4)/SUMPRODUCT($F799:$L799/$F$4:$L$4)*100} -> 0 | R799: {=(J799/$J$4)/SUMPRODUCT($F799:$L799/$F$4:$L$4)*100} -> 0 | S799: {=(K799/$K$4)/SUMPRODUCT($F799:$L799/$F$4:$L$4)*100} -> 0 | T799: {=(L799/$L$4)/SUMPRODUCT($F799:$L799/$F$4:$L$4)*100} -> 0.069525955 | U799: =SUM(N799:T799) -> 100 | V799: =IF(K799<>0,J799/(K799),0) -> 0 | W799: =J799+K799 -> 0 | X799: =J799*K799 -> 0 | Y799: =IF(J799+K799<>0,I799/(J799+K799),0) -> 0 | Z799: =IF(J799+K799<>0,L799/(J799+K799),0) -> 0 | AA799: =IF(L799<>0,H799/(L799),0) -> 10 | AB799: =H799+L799 -> 1.1 | AC799: =H799*L799 -> 0.1 | AD799: =IF(H799<>0,P799/(H799),0) -> 1.219793 | AE799: =IF(J799+K799<>0,H799/(J799+K799),0) -> 0 | AF799: =IF(H799<>0,(J799+K799)/(H799),0) -> 0 | AG799: =(J799+K799)*H799 -> 0 | AH799: =(100-N799)% -> 0.01289319 | AI799: {=SQRT(SUMPRODUCT(N799:T799/100,(1-($N$4:$T$4/(SUMPRODUCT(N799:T799,$N$4:$T$4)/100)))^2))} -> 0.0065885066 | AJ799: {=SUMPRODUCT(N799:T799,$N$3:$T$3)/100} -> 1.8966762 | AK799: {=SUMPRODUCT(N799:T799/100,($N$3:$T$3-(SUMPRODUCT(N799:T799,$N$3:$T$3)/100))^2)} -> 0.00091744295 | AL799: {=SUMPRODUCT(N799:T799/100,($N$2:$T$2-(SUMPRODUCT(N799:T799,$N$2:$T$2)/100))^2)} -> 0.3346789 | AM799: {=SUMPRODUCT(N799:T799,$N$2:$T$2)/100} -> 10.934144 | AN799: {=SUMPRODUCT(N799:T799,$N$1:$T$1)/100} -> 1095.1869 | AO799: {=-8.314*SUMPRODUCT((N799:T799/100)*LN(N799:T799/100+0.000000000001))} -> 0.59540833 | AP799: {=SUMPRODUCT((N799:T799/100)^2)} -> 0.97452913 | AQ799: {=1/SUMPRODUCT((N799:T799/100)^2)} -> 1.0261366 | AR799: Solution ==> Quenching ==> Deformation ==> Aging | AS799: =IF(AR799="Solution ==> Quenching ==> Deformation ==> Aging ==> Secondary TMP ==> Secondary Aging",2,IF(AR799="Solution ==> Quenching ==> Deformation ==> Aging",1,IF(AR799="Solution ==> Quenching ==> Aging",0,""))) -> 1 | AT799: 960/°C | AU799: 1 | AV799: N/A | AW799: N/A | AX799: N/A | AY799: =AV799%*AW799 -> #VALUE! | AZ799: =AV799%*AX799 -> #VALUE! | BA799: =AW799*AX799 -> #VALUE! | BB799: =AT799-AW799 -> #VALUE! | BC799: N/A | BD799: 151.33 | BE799: N/A | BF799: 478.18/MPa | BG799: 36.67/% IACS | BH799: =IF(OR(BD799="",BG799=""),"",((BD799-AVERAGE($BD$6:$BD$1143))/_xlfn.STDEV.S($BD$6:$BD$1143))-$BJ$1*((AVERAGE($BG$6:$BG$1143)-BG799)/_xlfn.STDEV.S($BG$6:$BG$1143))) -> #VALUE! | BI799: =SQRT((1-(BD799-MIN($BD$6:$BD$1143))/(MAX($BD$6:$BD$1143)-MIN($BD$6:$BD$1143)))^2+(1-(BG799-MIN($BG$6:$BG$1143))/(MAX($BG$6:$BG$1143)-MIN($BG$6:$BG$1143)))^2) -> #VALUE!
A800: 1223 | B800: 10.1016/j.matlet.2017.04.039 | C800: =_xlfn.XLOOKUP(A800,All!$A:$A,All!$C:$C,"") -> Cu-Cr-Zr | D800: 1 | E800: 质量分数 | F800: =100-SUM(G800:L800) -> 99.2 | G800: 0 | H800: 0.3 | I800: 0 | J800: 0 | K800: 0 | L800: 0.5 | M800: 摩尔分数 | N800: {=(F800/$F$4)/SUMPRODUCT($F800:$L800/$F$4:$L$4)*100} -> 99.284455 | O800: {=(G800/$G$4)/SUMPRODUCT($F800:$L800/$F$4:$L$4)*100} -> 0 | P800: {=(H800/$H$4)/SUMPRODUCT($F800:$L800/$F$4:$L$4)*100} -> 0.36695188 | Q800: {=(I800/$I$4)/SUMPRODUCT($F800:$L800/$F$4:$L$4)*100} -> 0 | R800: {=(J800/$J$4)/SUMPRODUCT($F800:$L800/$F$4:$L$4)*100} -> 0 | S800: {=(K800/$K$4)/SUMPRODUCT($F800:$L800/$F$4:$L$4)*100} -> 0 | T800: {=(L800/$L$4)/SUMPRODUCT($F800:$L800/$F$4:$L$4)*100} -> 0.34859303 | U800: =SUM(N800:T800) -> 100 | V800: =IF(K800<>0,J800/(K800),0) -> 0 | W800: =J800+K800 -> 0 | X800: =J800*K800 -> 0 | Y800: =IF(J800+K800<>0,I800/(J800+K800),0) -> 0 | Z800: =IF(J800+K800<>0,L800/(J800+K800),0) -> 0 | AA800: =IF(L800<>0,H800/(L800),0) -> 0.6 | AB800: =H800+L800 -> 0.8 | AC800: =H800*L800 -> 0.15 | AD800: =IF(H800<>0,P800/(H800),0) -> 1.2231729 | AE800: =IF(J800+K800<>0,H800/(J800+K800),0) -> 0 | AF800: =IF(H800<>0,(J800+K800)/(H800),0) -> 0 | AG800: =(J800+K800)*H800 -> 0 | AH800: =(100-N800)% -> 0.0071554491 | AI800: {=SQRT(SUMPRODUCT(N800:T800/100,(1-($N$4:$T$4/(SUMPRODUCT(N800:T800,$N$4:$T$4)/100)))^2))} -> 0.014721863 | AJ800: {=SUMPRODUCT(N800:T800,$N$3:$T$3)/100} -> 1.8971323 | AK800: {=SUMPRODUCT(N800:T800/100,($N$3:$T$3-(SUMPRODUCT(N800:T800,$N$3:$T$3)/100))^2)} -> 0.0013357195 | AL800: {=SUMPRODUCT(N800:T800/100,($N$2:$T$2-(SUMPRODUCT(N800:T800,$N$2:$T$2)/100))^2)} -> 0.26072107 | AM800: {=SUMPRODUCT(N800:T800,$N$2:$T$2)/100} -> 10.957251 | AN800: {=SUMPRODUCT(N800:T800,$N$1:$T$1)/100} -> 1090.3232 | AO800: {=-8.314*SUMPRODUCT((N800:T800/100)*LN(N800:T800/100+0.000000000001))} -> 0.3943686 | AP800: {=SUMPRODUCT((N800:T800/100)^2)} -> 0.98576592 | AQ800: {=1/SUMPRODUCT((N800:T800/100)^2)} -> 1.0144396 | AR800: Solution ==> Quenching ==> Aging | AS800: =IF(AR800="Solution ==> Quenching ==> Deformation ==> Aging ==> Secondary TMP ==> Secondary Aging",2,IF(AR800="Solution ==> Quenching ==> Deformation ==> Aging",1,IF(AR800="Solution ==> Quenching ==> Aging",0,""))) -> 0 | AT800: 999.85 | AU800: 1 | AV800: 0 | AW800: 299.85 | AX800: 1 | AY800: =AV800%*AW800 -> 0 | AZ800: =AV800%*AX800 -> 0 | BA800: =AW800*AX800 -> 299.85 | BB800: =AT800-AW800 -> 700 | BC800: N | BD800: 86 | BE800: N/A | BF800: N/A | BG800: 33 | BH800: =IF(OR(BD800="",BG800=""),"",((BD800-AVERAGE($BD$6:$BD$1143))/_xlfn.STDEV.S($BD$6:$BD$1143))-$BJ$1*((AVERAGE($BG$6:$BG$1143)-BG800)/_xlfn.STDEV.S($BG$6:$BG$1143))) -> -1.6183296 | BI800: =SQRT((1-(BD800-MIN($BD$6:$BD$1143))/(MAX($BD$6:$BD$1143)-MIN($BD$6:$BD$1143)))^2+(1-(BG800-MIN($BG$6:$BG$1143))/(MAX($BG$6:$BG$1143)-MIN($BG$6:$BG$1143)))^2) -> 1.179304
